Workbook

Sheet LEEME
A1: Modelo financiero — agencia de creación de negocios — Fase 3 (2026-10-21)
A2: Generado por finanzas/modelo.py --xlsx. Las celdas amarillas son entradas; el resto son fórmulas.
A3: Para cambiar un supuesto, edite la celda amarilla en la hoja 'Supuestos' de la idea o en 'Globales'; todo se recalcula.
A4: Etiquetas de origen: VERIFICADO: fuente, fecha · ESTIMADO: método · SUPUESTO: por validar · DESCONOCIDO.
A5: Si cambia un valor aquí, replíquelo en modelo.py (o al revés) para que ambos coincidan.
A6: Las proyecciones son escenarios, no predicciones. Régimen tributario uniforme SUPUESTO (RER) hasta el informe legal.

Sheet Comparacion
A1: Comparación con el mismo método — escenario base salvo donde se indica
A2: Idea | B2: Inversión inicial | C2: Margen por unidad | D2: Margen % | E2: Punto de equilibrio (u/mes) | F2: Recupera (mes, base) | G2: Resultado 12 m (pesimista) | H2: Resultado 12 m (base) | I2: Resultado 12 m (optimista) | J2: Horas/semana (pico base) | K2: F1 inversión | L2: F1 fijos | M2: Unid./mes 1 sueldo | N2: Horas/sem 1 sueldo | O2: Mes cubre 1 sueldo (base) | P2: Mes cubre 1 sueldo (optimista) | Q2: Cabe en capital (base)
A3: 1. Chatbot WhatsApp + panel (fichas 08+09+14) | B3: ='I1 Unitario'!$B$14 | C3: ='I1 Unitario'!$B$9 | D3: ='I1 Unitario'!$B$10 | E3: ='I1 Unitario'!$B$12 | F3: ='I1 Flujo'!$N$34 | G3: ='I1 Flujo'!$N$15 | H3: ='I1 Flujo'!$N$33 | I3: ='I1 Flujo'!$N$51 | J3: ='I1 Supuestos'!$B$38 | K3: ='I1 Unitario'!$B$15 | L3: ='I1 Unitario'!$B$16 | M3: ='I1 Unitario'!$B$17 | N3: ='I1 Unitario'!$B$18 | O3: ='I1 Flujo'!$N$37 | P3: ='I1 Flujo'!$N$55 | Q3: ='I1 Flujo'!$N$36
A4: 2. Cliente incógnito + micro-capacitación (ficha 10) | B4: ='I2 Unitario'!$B$14 | C4: ='I2 Unitario'!$B$9 | D4: ='I2 Unitario'!$B$10 | E4: ='I2 Unitario'!$B$12 | F4: ='I2 Flujo'!$N$34 | G4: ='I2 Flujo'!$N$15 | H4: ='I2 Flujo'!$N$33 | I4: ='I2 Flujo'!$N$51 | J4: ='I2 Supuestos'!$B$37 | K4: ='I2 Unitario'!$B$15 | L4: ='I2 Unitario'!$B$16 | M4: ='I2 Unitario'!$B$17 | N4: ='I2 Unitario'!$B$18 | O4: ='I2 Flujo'!$N$37 | P4: ='I2 Flujo'!$N$55 | Q4: ='I2 Flujo'!$N$36
A5: 3. Taller 'construye tu app con IA' (ficha 13) | B5: ='I3 Unitario'!$B$14 | C5: ='I3 Unitario'!$B$9 | D5: ='I3 Unitario'!$B$10 | E5: ='I3 Unitario'!$B$12 | F5: ='I3 Flujo'!$N$34 | G5: ='I3 Flujo'!$N$15 | H5: ='I3 Flujo'!$N$33 | I5: ='I3 Flujo'!$N$51 | J5: ='I3 Supuestos'!$B$36 | K5: ='I3 Unitario'!$B$15 | L5: ='I3 Unitario'!$B$16 | M5: ='I3 Unitario'!$B$17 | N5: ='I3 Unitario'!$B$18 | O5: ='I3 Flujo'!$N$37 | P5: ='I3 Flujo'!$N$55 | Q5: ='I3 Flujo'!$N$36
A6: 4. Sorpresas y detalles a domicilio (ficha 06) | B6: ='I4 Unitario'!$B$14 | C6: ='I4 Unitario'!$B$9 | D6: ='I4 Unitario'!$B$10 | E6: ='I4 Unitario'!$B$12 | F6: ='I4 Flujo'!$N$34 | G6: ='I4 Flujo'!$N$15 | H6: ='I4 Flujo'!$N$33 | I6: ='I4 Flujo'!$N$51 | J6: ='I4 Supuestos'!$B$37 | K6: ='I4 Unitario'!$B$15 | L6: ='I4 Unitario'!$B$16 | M6: ='I4 Unitario'!$B$17 | N6: ='I4 Unitario'!$B$18 | O6: ='I4 Flujo'!$N$37 | P6: ='I4 Flujo'!$N$55 | Q6: ='I4 Flujo'!$N$36
A7: 5. Decoración para eventos pequeños (ficha 05) | B7: ='I5 Unitario'!$B$14 | C7: ='I5 Unitario'!$B$9 | D7: ='I5 Unitario'!$B$10 | E7: ='I5 Unitario'!$B$12 | F7: ='I5 Flujo'!$N$34 | G7: ='I5 Flujo'!$N$15 | H7: ='I5 Flujo'!$N$33 | I7: ='I5 Flujo'!$N$51 | J7: ='I5 Supuestos'!$B$39 | K7: ='I5 Unitario'!$B$15 | L7: ='I5 Unitario'!$B$16 | M7: ='I5 Unitario'!$B$17 | N7: ='I5 Unitario'!$B$18 | O7: ='I5 Flujo'!$N$37 | P7: ='I5 Flujo'!$N$55 | Q7: ='I5 Flujo'!$N$36

Sheet Globales
A1: Parámetro | B1: Valor | C1: Origen
A2: Capital inicial (S/) | B2: 400 | C2: VERIFICADO: expediente/00-perfil-socios.md (Indira S/ 400; Carlos S/ 0), 2026-10-21
A3: Aporte mensual máximo (S/) | B3: 350 | C3: VERIFICADO: expediente/00-perfil-socios.md (Carlos 150 + Indira 200), 2026-10-21
A4: Tope inversión F1 (S/) | B4: 400 | C4: VERIFICADO: expediente/decisiones.md, filtro F1, 2026-10-21
A5: Tope fijos F1 (S/ por mes) | B5: 150 | C5: VERIFICADO: expediente/decisiones.md, filtro F1 (gasto mensual hasta la 1.ª venta), 2026-10-21
A6: Tope horas F2 (h/semana) | B6: 34 | C6: VERIFICADO: expediente/decisiones.md, filtro F2 (34 h/semana entre los dos en exámenes), 2026-10-21
A7: Tipo de cambio (S/ por US$) | B7: 3.44 | C7: VERIFICADO: open.er-api.com, 2026-10-21 (3,4376 S/ por US$, redondeado)
A8: RMV (S/) | B8: 1130 | C8: VERIFICADO: D.S. 006-2024-TR, RMV S/ 1 130 vigente desde 2025-01-01; no se verificó hoy si hubo aumento en 2026
A9: Sueldo objetivo por socio (S/ por mes) | B9: 2000 | C9: SUPUESTO: por validar — sueldo neto mensual de UN socio; los sueldos reales de Carlos e Indira no están registrados [DESCONOCIDO]. Se usa S/ 2 000 (entre la RMV de S/ 1 130 y el promedio de community manager S/ 1 346 citado en el informe del explorador, con margen para un puesto con estudios). Los socios deben confirmarlo
A10: Cuota Nuevo RUS cat. 1 (S/ por mes) | B10: 20 | C10: VERIFICADO: D. Leg. 937 modificado por D. Leg. 1270, Nuevo RUS categoría 1 (ingresos ≤ S/ 5 000/mes), cuota S/ 20; norma conocida, no verificada hoy — confirmar con asesor-legal-tributario-peru
A11: Retención 4.ª categoría | B11: 0.08 | C11: VERIFICADO: retención de rentas de 4.ª categoría 8 % (recibos por honorarios > S/ 1 500); norma conocida, no verificada hoy — confirmar con asesor legal; solo aplica a servicios personales (ideas 2 y 3)
A12: Pasarela alternativa % | B12: 0.0344 | C12: VERIFICADO: culqi.com/precios, 2026-10-21 — online y link de pago, tarjetas nacionales y billeteras
A13: Pasarela alternativa fijo (S/) | B13: 0.688 | C13: VERIFICADO: culqi.com/precios, 2026-10-21 — US$ 0,20 por transacción × tipo de cambio

Sheet I1 Supuestos
A1: Idea: 1. Chatbot WhatsApp + panel (fichas 08+09+14)
A2: Unidad: una mensualidad de un cliente activo
A3: Concepto | B3: Valor | C3: Origen | D3: Nota
A4: Precio de venta al cliente (S/) | B4: 150 | C4: SUPUESTO: por validar — punto medio del rango S/ 80–200/mes de las fichas 08/09 (S-10); con IGV incluido
A5: ¿Precio incluye IGV? (1 = sí, 0 = no) | B5: 1 | C5: regla
A6: Tasa IGV | B6: 0.18 | C6: VERIFICADO: TUO Ley del IGV (16 %) + IPM (2 %) = 18 %, vigente; sin informe legal aún — confirmar con asesor-legal-tributario-peru | D6: precio al cliente con IGV incluido
A7: Comisión pasarela (%) | B7: 0 | C7: SUPUESTO: por validar — cobro por Yape/Plin o transferencia entre personas naturales, sin comisión; la variante con Culqi (3,44 % + US$ 0,20) se calcula aparte
A8: Comisión pasarela fija por transacción (S/) | B8: 0 | C8: SUPUESTO: por validar — igual que tasa_pasarela
A9: Impuesto a la renta (% sobre ingreso neto) | B9: 0.015 | C9: SUPUESTO: por validar — RER (1,5 % de ingresos netos mensuales) como régimen uniforme y conservador para las cinco ideas; permite emitir factura a negocios. Variantes Nuevo RUS y 4.ª categoría se calculan aparte. Lo define el asesor legal en la Etapa 2
A10: Horas fijas por semana | B10: 12 | C10: ESTIMADO: mantenimiento y mejoras 6 h (Carlos) + demos y venta 4 h (Indira) + administración 2 h. NO incluye las 80–120 h de construcción previas al mes 1 (4–6 semanas × 20 h, ficha 08)
A11: Horas por unidad vendida | B11: 2 | C11: ESTIMADO: configuración inicial 4 h (ficha 08: 3–5 h) prorrateada en 4 meses de permanencia + 1 h/mes de soporte por cliente
A13: Inversión inicial (S/)
A14: chip / número de WhatsApp dedicado | B14: 15 | C14: ESTIMADO: ficha 08 (S/ 10–20), punto medio
A15: dominio para el panel (1 año) | B15: 50 | C15: ESTIMADO: ficha 14 (S/ 40–60)
A16: hosting e IA durante la construcción, antes de la 1.ª venta (1,5 meses) | B16: 105 | C16: ESTIMADO: 4–6 semanas de construcción (ficha 08) × los dos costos fijos mensuales de abajo
A17: verificación de negocio en Meta | B17: 0 | C17: ESTIMADO: Meta no publica tarifa por verificar el negocio; cobra por mensaje (ficha 08)
A18: TOTAL inversión inicial (s/) | B18: =SUM(B14:B17) | C18: fórmula
A20: Costos fijos mensuales (S/)
A21: servidor / hosting (VPS básico) | B21: 35 | C21: ESTIMADO: ficha 08 (S/ 20–50/mes); ~US$ 10 × TC 3,44
A22: plataforma de IA (cuenta, pruebas; no por cliente) | B22: 35 | C22: ESTIMADO: ficha 08 (S/ 20–60/mes), punto medio bajo
A23: contabilidad / declaraciones | B23: 0 | C23: SUPUESTO: por validar — declaran ellos mismos en SUNAT Virtual; un contador costaría S/ 50–150/mes
A24: TOTAL costos fijos mensuales (s/) | B24: =SUM(B21:B23) | C24: fórmula
A26: Costo variable directo por unidad (S/)
A27: API de Meta: mensajes de plantilla por cliente/mes | B27: 13.072 | C27: ESTIMADO: 100 mensajes de plantilla de utilidad por cliente/mes × US$ 0,038 (ficha 08: SleekFlow 2025) × TC 3,44; las respuestas dentro de la ventana de 24 h no pagan
A28: IA / tokens por cliente/mes | B28: 15 | C28: ESTIMADO: ~1 500 respuestas/mes × ~S/ 0,01 por respuesta con un modelo económico; sin medición real
A29: servidor incremental por cliente/mes | B29: 5 | C29: ESTIMADO: el VPS básico soporta ~10 clientes; se prorratea la ampliación
A30: TOTAL costo variable directo por unidad (s/) | B30: =SUM(B27:B29) | C30: fórmula
A32: Escenarios
A33: Escenario | B33: Unidades mes 1 | C33: Crecimiento mensual | D33: Factor precio | E33: Origen
A34: pesimista | B34: 1 | C34: 0 | D34: 0.66666667 | E34: SUPUESTO: por validar — solo el piloto con la academia de marinera (S-14) a S/ 100 (precio de contacto) y ningún cliente nuevo en 12 meses: primera venta en la vida de los socios y canal solo por referidos
A35: base | B35: 2 | C35: 0.2 | D35: 1 | E35: SUPUESTO: por validar — 2 contactos (academia, librería) pagan desde el mes 1; +20 %/mes neto de bajas, solo por referidos
A36: optimista | B36: 3 | C36: 0.25 | D36: 1 | E36: SUPUESTO: por validar — 3 clientes en el mes 1 (academia, librería, galletas) y +25 %/mes neto con referidos y contenido en redes
A38: Horas/semana requeridas (pico: mes 12 del escenario base) | B38: ='I1 Supuestos'!$B$10+'I1 Supuestos'!$B$11*'I1 Supuestos'!$B$35*(1+'I1 Supuestos'!$C$35)^(12-1)/(4.333333333333333) | C38: ESTIMADO: horas fijas/semana + horas por unidad × unidades del mes 12 del escenario base ÷ 4,33 semanas/mes (pico del año 1)
A39: Rango del precio por validar (mín – máx) | B39: 80 | C39: 200 | D39: ver hoja Unitario

Sheet I1 Unitario
A1: Economía unitaria — 1. Chatbot WhatsApp + panel (fichas 08+09+14) (precio de lista)
A2: Concepto | B2: S/ | C2: Fórmula
A3: Precio al cliente | B3: ='I1 Supuestos'!$B$4 | C3: '='I1 Supuestos'!$B$4
A4: Ingreso neto (sin IGV) | B4: =IF('I1 Supuestos'!$B$5=1,'I1 Unitario'!$B$3/(1+'I1 Supuestos'!$B$6),'I1 Unitario'!$B$3) | C4: '=IF('I1 Supuestos'!$B$5=1,'I1 Unitario'!$B$3/(1+'I1 Supuestos'!$B$6),'I1 Unitario'!$B$3)
A5: Comisión pasarela | B5: ='I1 Unitario'!$B$3*'I1 Supuestos'!$B$7+'I1 Supuestos'!$B$8 | C5: '='I1 Unitario'!$B$3*'I1 Supuestos'!$B$7+'I1 Supuestos'!$B$8
A6: Impuesto a la renta | B6: ='I1 Unitario'!$B$4*'I1 Supuestos'!$B$9 | C6: '='I1 Unitario'!$B$4*'I1 Supuestos'!$B$9
A7: Costo variable directo | B7: ='I1 Supuestos'!$B$30 | C7: '='I1 Supuestos'!$B$30
A8: Costo variable total | B8: ='I1 Unitario'!$B$7+'I1 Unitario'!$B$5+'I1 Unitario'!$B$6 | C8: '='I1 Unitario'!$B$7+'I1 Unitario'!$B$5+'I1 Unitario'!$B$6
A9: Margen por unidad | B9: ='I1 Unitario'!$B$4-'I1 Unitario'!$B$8 | C9: '='I1 Unitario'!$B$4-'I1 Unitario'!$B$8
A10: Margen % sobre ingreso neto | B10: =IF('I1 Unitario'!$B$4=0,0,'I1 Unitario'!$B$9/'I1 Unitario'!$B$4) | C10: '=IF('I1 Unitario'!$B$4=0,0,'I1 Unitario'!$B$9/'I1 Unitario'!$B$4)
A11: Costos fijos mensuales | B11: ='I1 Supuestos'!$B$24 | C11: '='I1 Supuestos'!$B$24
A12: Punto de equilibrio (unidades/mes) | B12: =IF('I1 Unitario'!$B$9>0,'I1 Unitario'!$B$11/'I1 Unitario'!$B$9,"no alcanzable") | C12: '=IF('I1 Unitario'!$B$9>0,'I1 Unitario'!$B$11/'I1 Unitario'!$B$9,"no alcanzable")
A13: Punto de equilibrio (S/ ventas/mes) | B13: =IF(ISNUMBER('I1 Unitario'!$B$12),'I1 Unitario'!$B$12*'I1 Unitario'!$B$3,"no alcanzable") | C13: '=IF(ISNUMBER('I1 Unitario'!$B$12),'I1 Unitario'!$B$12*'I1 Unitario'!$B$3,"no alcanzable")
A14: Inversión inicial | B14: ='I1 Supuestos'!$B$18 | C14: '='I1 Supuestos'!$B$18
A15: F1: inversión ≤ tope | B15: =IF('I1 Unitario'!$B$14<=Globales!$B$4,"sí","NO") | C15: '=IF('I1 Unitario'!$B$14<=Globales!$B$4,"sí","NO")
A16: F1: fijos ≤ tope mensual | B16: =IF('I1 Unitario'!$B$11<=Globales!$B$5,"sí","NO") | C16: '=IF('I1 Unitario'!$B$11<=Globales!$B$5,"sí","NO")
A17: Unidades/mes para cubrir 1 sueldo | B17: =IF('I1 Unitario'!$B$9>0,('I1 Unitario'!$B$11+Globales!$B$9)/'I1 Unitario'!$B$9,"no alcanzable") | C17: '=IF('I1 Unitario'!$B$9>0,('I1 Unitario'!$B$11+Globales!$B$9)/'I1 Unitario'!$B$9,"no alcanzable")
A18: Horas/semana para cubrir 1 sueldo | B18: =IF(ISNUMBER('I1 Unitario'!$B$17),'I1 Supuestos'!$B$10+'I1 Supuestos'!$B$11*'I1 Unitario'!$B$17/(4.333333333333333),"n/a") | C18: '=IF(ISNUMBER('I1 Unitario'!$B$17),'I1 Supuestos'!$B$10+'I1 Supuestos'!$B$11*'I1 Unitario'!$B$17/(4.333333333333333),"n/a")
A19: Unidades/mes para cubrir 2 sueldos | B19: =IF('I1 Unitario'!$B$9>0,('I1 Unitario'!$B$11+2*Globales!$B$9)/'I1 Unitario'!$B$9,"no alcanzable") | C19: '=IF('I1 Unitario'!$B$9>0,('I1 Unitario'!$B$11+2*Globales!$B$9)/'I1 Unitario'!$B$9,"no alcanzable")
A20: Horas/semana para cubrir 2 sueldos | B20: =IF(ISNUMBER('I1 Unitario'!$B$19),'I1 Supuestos'!$B$10+'I1 Supuestos'!$B$11*'I1 Unitario'!$B$19/(4.333333333333333),"n/a") | C20: '=IF(ISNUMBER('I1 Unitario'!$B$19),'I1 Supuestos'!$B$10+'I1 Supuestos'!$B$11*'I1 Unitario'!$B$19/(4.333333333333333),"n/a")
A22: Variantes (mismo precio de lista) | B22: Margen/u
A23: Nuevo RUS cat. 1: sin IGV, sin renta %, +cuota como fijo → margen | B23: ='I1 Unitario'!$B$3-('I1 Unitario'!$B$7+'I1 Unitario'!$B$5) | C23: '='I1 Unitario'!$B$3-('I1 Unitario'!$B$7+'I1 Unitario'!$B$5)
A24: Nuevo RUS: punto de equilibrio (u/mes) | B24: =IF('I1 Unitario'!$B$23>0,('I1 Unitario'!$B$11+Globales!$B$10)/'I1 Unitario'!$B$23,"no alcanzable") | C24: '=IF('I1 Unitario'!$B$23>0,('I1 Unitario'!$B$11+Globales!$B$10)/'I1 Unitario'!$B$23,"no alcanzable")
A25: 4.ª categoría: sin IGV, retención 8 % → margen | B25: ='I1 Unitario'!$B$3-('I1 Unitario'!$B$7+'I1 Unitario'!$B$5+'I1 Unitario'!$B$3*Globales!$B$11) | C25: '='I1 Unitario'!$B$3-('I1 Unitario'!$B$7+'I1 Unitario'!$B$5+'I1 Unitario'!$B$3*Globales!$B$11)
A26: RER + pasarela Culqi → margen | B26: ='I1 Unitario'!$B$4-('I1 Unitario'!$B$7+'I1 Unitario'!$B$3*Globales!$B$12+Globales!$B$13+'I1 Unitario'!$B$6) | C26: '='I1 Unitario'!$B$4-('I1 Unitario'!$B$7+'I1 Unitario'!$B$3*Globales!$B$12+Globales!$B$13+'I1 Unitario'!$B$6)
A27: Margen/u con precio mínimo del rango | B27: =IF('I1 Supuestos'!$B$5=1,'I1 Supuestos'!$B$39/(1+'I1 Supuestos'!$B$6),'I1 Supuestos'!$B$39)-('I1 Unitario'!$B$7+'I1 Supuestos'!$B$39*'I1 Supuestos'!$B$7+'I1 Supuestos'!$B$8+IF('I1 Supuestos'!$B$5=1,'I1 Supuestos'!$B$39/(1+'I1 Supuestos'!$B$6),'I1 Supuestos'!$B$39)*'I1 Supuestos'!$B$9) | C27: '=IF('I1 Supuestos'!$B$5=1,'I1 Supuestos'!$B$39/(1+'I1 Supuestos'!$B$6),'I1 Supuestos'!$B$39)-('I1 Unitario'!$B$7+'I1 Supuestos'!$B$39*'I1 Supuestos'!$B$7+'I1 Supuestos'!$B$8+IF('I1 Supuestos'!$B$5=1,'I1 Supuestos'!$B$39/(1+'I1 Supuestos'!$B$6),'I1 Supuestos'!$B$39)*'I1 Supuestos'!$B$9)
A28: Margen/u con precio máximo del rango | B28: =IF('I1 Supuestos'!$B$5=1,'I1 Supuestos'!$C$39/(1+'I1 Supuestos'!$B$6),'I1 Supuestos'!$C$39)-('I1 Unitario'!$B$7+'I1 Supuestos'!$C$39*'I1 Supuestos'!$B$7+'I1 Supuestos'!$B$8+IF('I1 Supuestos'!$B$5=1,'I1 Supuestos'!$C$39/(1+'I1 Supuestos'!$B$6),'I1 Supuestos'!$C$39)*'I1 Supuestos'!$B$9) | C28: '=IF('I1 Supuestos'!$B$5=1,'I1 Supuestos'!$C$39/(1+'I1 Supuestos'!$B$6),'I1 Supuestos'!$C$39)-('I1 Unitario'!$B$7+'I1 Supuestos'!$C$39*'I1 Supuestos'!$B$7+'I1 Supuestos'!$B$8+IF('I1 Supuestos'!$B$5=1,'I1 Supuestos'!$C$39/(1+'I1 Supuestos'!$B$6),'I1 Supuestos'!$C$39)*'I1 Supuestos'!$B$9)

Sheet I1 Flujo
A1: Flujo de caja a 12 meses — 1. Chatbot WhatsApp + panel (fichas 08+09+14). Escenarios, no predicciones.
A3: Escenario pesimista
A4: Precio escenario | B4: ='I1 Supuestos'!$B$4*'I1 Supuestos'!$D$34
A5: Ingreso neto unitario | B5: =IF('I1 Supuestos'!$B$5=1,B4/(1+'I1 Supuestos'!$B$6),B4)
A6: Costo variable total unitario | B6: ='I1 Supuestos'!$B$30+B4*'I1 Supuestos'!$B$7+'I1 Supuestos'!$B$8+B5*'I1 Supuestos'!$B$9
A7: Costos fijos mensuales | B7: ='I1 Supuestos'!$B$24
A8: Inversión inicial | B8: ='I1 Supuestos'!$B$18
A9: Mes | B9: 1 | C9: 2 | D9: 3 | E9: 4 | F9: 5 | G9: 6 | H9: 7 | I9: 8 | J9: 9 | K9: 10 | L9: 11 | M9: 12 | N9: Total 12 m
A10: Unidades | B10: ='I1 Supuestos'!$B$34*(1+'I1 Supuestos'!$C$34)^(1-1) | C10: ='I1 Supuestos'!$B$34*(1+'I1 Supuestos'!$C$34)^(2-1) | D10: ='I1 Supuestos'!$B$34*(1+'I1 Supuestos'!$C$34)^(3-1) | E10: ='I1 Supuestos'!$B$34*(1+'I1 Supuestos'!$C$34)^(4-1) | F10: ='I1 Supuestos'!$B$34*(1+'I1 Supuestos'!$C$34)^(5-1) | G10: ='I1 Supuestos'!$B$34*(1+'I1 Supuestos'!$C$34)^(6-1) | H10: ='I1 Supuestos'!$B$34*(1+'I1 Supuestos'!$C$34)^(7-1) | I10: ='I1 Supuestos'!$B$34*(1+'I1 Supuestos'!$C$34)^(8-1) | J10: ='I1 Supuestos'!$B$34*(1+'I1 Supuestos'!$C$34)^(9-1) | K10: ='I1 Supuestos'!$B$34*(1+'I1 Supuestos'!$C$34)^(10-1) | L10: ='I1 Supuestos'!$B$34*(1+'I1 Supuestos'!$C$34)^(11-1) | M10: ='I1 Supuestos'!$B$34*(1+'I1 Supuestos'!$C$34)^(12-1) | N10: =SUM(B10:M10)
A11: Ingresos netos | B11: =B10*$B$5 | C11: =C10*$B$5 | D11: =D10*$B$5 | E11: =E10*$B$5 | F11: =F10*$B$5 | G11: =G10*$B$5 | H11: =H10*$B$5 | I11: =I10*$B$5 | ... M11: =M10*$B$5 | N11: =SUM(B11:M11)
A12: Costos variables | B12: =B10*$B$6 | C12: =C10*$B$6 | D12: =D10*$B$6 | E12: =E10*$B$6 | F12: =F10*$B$6 | G12: =G10*$B$6 | H12: =H10*$B$6 | I12: =I10*$B$6 | ... M12: =M10*$B$6 | N12: =SUM(B12:M12)
A13: Costos fijos | B13: =$B$7 | C13: =$B$7 | D13: =$B$7 | E13: =$B$7 | F13: =$B$7 | G13: =$B$7 | H13: =$B$7 | I13: =$B$7 | ... M13: =$B$7 | N13: =SUM(B13:M13)
A14: Flujo neto | B14: =B11-B12-B13 | C14: =C11-C12-C13 | D14: =D11-D12-D13 | E14: =E11-E12-E13 | F14: =F11-F12-F13 | G14: =G11-G12-G13 | H14: =H11-H12-H13 | I14: =I11-I12-I13 | ... M14: =M11-M12-M13 | N14: =SUM(B14:M14)
A15: Acumulado (tras inversión) | B15: =-$B$8+B14 | C15: =B15+C14 | D15: =C15+D14 | E15: =D15+E14 | F15: =E15+F14 | G15: =F15+G14 | H15: =G15+H14 | I15: =H15+I14 | J15: =I15+J14 | ... M15: =L15+M14 | N15: =M15
A16: Mes en que acumulado ≥ 0 | B16: =IF(B15>=0,1,"") | C16: =IF(C15>=0,2,"") | D16: =IF(D15>=0,3,"") | E16: =IF(E15>=0,4,"") | F16: =IF(F15>=0,5,"") | G16: =IF(G15>=0,6,"") | H16: =IF(H15>=0,7,"") | I16: =IF(I15>=0,8,"") | J16: =IF(J15>=0,9,"") | K16: =IF(K15>=0,10,"") | L16: =IF(L15>=0,11,"") | M16: =IF(M15>=0,12,"") | N16: =IF(COUNT(B16:M16)=0,"no en 12 meses",MIN(B16:M16))
A17: Horas/semana | B17: ='I1 Supuestos'!$B$10+'I1 Supuestos'!$B$11*B10/(4.333333333333333) | C17: ='I1 Supuestos'!$B$10+'I1 Supuestos'!$B$11*C10/(4.333333333333333) | D17: ='I1 Supuestos'!$B$10+'I1 Supuestos'!$B$11*D10/(4.333333333333333) | E17: ='I1 Supuestos'!$B$10+'I1 Supuestos'!$B$11*E10/(4.333333333333333) | F17: ='I1 Supuestos'!$B$10+'I1 Supuestos'!$B$11*F10/(4.333333333333333) | G17: ='I1 Supuestos'!$B$10+'I1 Supuestos'!$B$11*G10/(4.333333333333333) | H17: ='I1 Supuestos'!$B$10+'I1 Supuestos'!$B$11*H10/(4.333333333333333) | I17: ='I1 Supuestos'!$B$10+'I1 Supuestos'!$B$11*I10/(4.333333333333333) | ... M17: ='I1 Supuestos'!$B$10+'I1 Supuestos'!$B$11*M10/(4.333333333333333) | N17: =MAX(B17:M17)
A18: Capital disponible (inicial + aportes) | B18: =Globales!$B$2+Globales!$B$3*1 | C18: =Globales!$B$2+Globales!$B$3*2 | D18: =Globales!$B$2+Globales!$B$3*3 | E18: =Globales!$B$2+Globales!$B$3*4 | F18: =Globales!$B$2+Globales!$B$3*5 | G18: =Globales!$B$2+Globales!$B$3*6 | H18: =Globales!$B$2+Globales!$B$3*7 | I18: =Globales!$B$2+Globales!$B$3*8 | J18: =Globales!$B$2+Globales!$B$3*9 | K18: =Globales!$B$2+Globales!$B$3*10 | L18: =Globales!$B$2+Globales!$B$3*11 | M18: =Globales!$B$2+Globales!$B$3*12 | N18: =IF(SUMPRODUCT(--(-B15:M15>B18:M18))=0,"cabe en el capital","NO cabe")
A19: Mes en que flujo neto ≥ 1 sueldo | B19: =IF(B14>=Globales!$B$9,1,"") | C19: =IF(C14>=Globales!$B$9,2,"") | D19: =IF(D14>=Globales!$B$9,3,"") | E19: =IF(E14>=Globales!$B$9,4,"") | F19: =IF(F14>=Globales!$B$9,5,"") | G19: =IF(G14>=Globales!$B$9,6,"") | H19: =IF(H14>=Globales!$B$9,7,"") | I19: =IF(I14>=Globales!$B$9,8,"") | J19: =IF(J14>=Globales!$B$9,9,"") | K19: =IF(K14>=Globales!$B$9,10,"") | L19: =IF(L14>=Globales!$B$9,11,"") | M19: =IF(M14>=Globales!$B$9,12,"") | N19: =IF(COUNT(B19:M19)=0,"no en 12 meses",MIN(B19:M19))
A21: Escenario base
A22: Precio escenario | B22: ='I1 Supuestos'!$B$4*'I1 Supuestos'!$D$35
A23: Ingreso neto unitario | B23: =IF('I1 Supuestos'!$B$5=1,B22/(1+'I1 Supuestos'!$B$6),B22)
A24: Costo variable total unitario | B24: ='I1 Supuestos'!$B$30+B22*'I1 Supuestos'!$B$7+'I1 Supuestos'!$B$8+B23*'I1 Supuestos'!$B$9
A25: Costos fijos mensuales | B25: ='I1 Supuestos'!$B$24
A26: Inversión inicial | B26: ='I1 Supuestos'!$B$18
A27: Mes | B27: 1 | C27: 2 | D27: 3 | E27: 4 | F27: 5 | G27: 6 | H27: 7 | I27: 8 | J27: 9 | K27: 10 | L27: 11 | M27: 12 | N27: Total 12 m
A28: Unidades | B28: ='I1 Supuestos'!$B$35*(1+'I1 Supuestos'!$C$35)^(1-1) | C28: ='I1 Supuestos'!$B$35*(1+'I1 Supuestos'!$C$35)^(2-1) | D28: ='I1 Supuestos'!$B$35*(1+'I1 Supuestos'!$C$35)^(3-1) | E28: ='I1 Supuestos'!$B$35*(1+'I1 Supuestos'!$C$35)^(4-1) | F28: ='I1 Supuestos'!$B$35*(1+'I1 Supuestos'!$C$35)^(5-1) | G28: ='I1 Supuestos'!$B$35*(1+'I1 Supuestos'!$C$35)^(6-1) | H28: ='I1 Supuestos'!$B$35*(1+'I1 Supuestos'!$C$35)^(7-1) | I28: ='I1 Supuestos'!$B$35*(1+'I1 Supuestos'!$C$35)^(8-1) | J28: ='I1 Supuestos'!$B$35*(1+'I1 Supuestos'!$C$35)^(9-1) | K28: ='I1 Supuestos'!$B$35*(1+'I1 Supuestos'!$C$35)^(10-1) | L28: ='I1 Supuestos'!$B$35*(1+'I1 Supuestos'!$C$35)^(11-1) | M28: ='I1 Supuestos'!$B$35*(1+'I1 Supuestos'!$C$35)^(12-1) | N28: =SUM(B28:M28)
A29: Ingresos netos | B29: =B28*$B$23 | C29: =C28*$B$23 | D29: =D28*$B$23 | E29: =E28*$B$23 | F29: =F28*$B$23 | G29: =G28*$B$23 | H29: =H28*$B$23 | I29: =I28*$B$23 | ... M29: =M28*$B$23 | N29: =SUM(B29:M29)
A30: Costos variables | B30: =B28*$B$24 | C30: =C28*$B$24 | D30: =D28*$B$24 | E30: =E28*$B$24 | F30: =F28*$B$24 | G30: =G28*$B$24 | H30: =H28*$B$24 | I30: =I28*$B$24 | ... M30: =M28*$B$24 | N30: =SUM(B30:M30)
A31: Costos fijos | B31: =$B$25 | C31: =$B$25 | D31: =$B$25 | E31: =$B$25 | F31: =$B$25 | G31: =$B$25 | H31: =$B$25 | I31: =$B$25 | ... M31: =$B$25 | N31: =SUM(B31:M31)
A32: Flujo neto | B32: =B29-B30-B31 | C32: =C29-C30-C31 | D32: =D29-D30-D31 | E32: =E29-E30-E31 | F32: =F29-F30-F31 | G32: =G29-G30-G31 | H32: =H29-H30-H31 | I32: =I29-I30-I31 | ... M32: =M29-M30-M31 | N32: =SUM(B32:M32)
A33: Acumulado (tras inversión) | B33: =-$B$26+B32 | C33: =B33+C32 | D33: =C33+D32 | E33: =D33+E32 | F33: =E33+F32 | G33: =F33+G32 | H33: =G33+H32 | I33: =H33+I32 | J33: =I33+J32 | ... M33: =L33+M32 | N33: =M33
A34: Mes en que acumulado ≥ 0 | B34: =IF(B33>=0,1,"") | C34: =IF(C33>=0,2,"") | D34: =IF(D33>=0,3,"") | E34: =IF(E33>=0,4,"") | F34: =IF(F33>=0,5,"") | G34: =IF(G33>=0,6,"") | H34: =IF(H33>=0,7,"") | I34: =IF(I33>=0,8,"") | J34: =IF(J33>=0,9,"") | K34: =IF(K33>=0,10,"") | L34: =IF(L33>=0,11,"") | M34: =IF(M33>=0,12,"") | N34: =IF(COUNT(B34:M34)=0,"no en 12 meses",MIN(B34:M34))
A35: Horas/semana | B35: ='I1 Supuestos'!$B$10+'I1 Supuestos'!$B$11*B28/(4.333333333333333) | C35: ='I1 Supuestos'!$B$10+'I1 Supuestos'!$B$11*C28/(4.333333333333333) | D35: ='I1 Supuestos'!$B$10+'I1 Supuestos'!$B$11*D28/(4.333333333333333) | E35: ='I1 Supuestos'!$B$10+'I1 Supuestos'!$B$11*E28/(4.333333333333333) | F35: ='I1 Supuestos'!$B$10+'I1 Supuestos'!$B$11*F28/(4.333333333333333) | G35: ='I1 Supuestos'!$B$10+'I1 Supuestos'!$B$11*G28/(4.333333333333333) | H35: ='I1 Supuestos'!$B$10+'I1 Supuestos'!$B$11*H28/(4.333333333333333) | I35: ='I1 Supuestos'!$B$10+'I1 Supuestos'!$B$11*I28/(4.333333333333333) | ... M35: ='I1 Supuestos'!$B$10+'I1 Supuestos'!$B$11*M28/(4.333333333333333) | N35: =MAX(B35:M35)
A36: Capital disponible (inicial + aportes) | B36: =Globales!$B$2+Globales!$B$3*1 | C36: =Globales!$B$2+Globales!$B$3*2 | D36: =Globales!$B$2+Globales!$B$3*3 | E36: =Globales!$B$2+Globales!$B$3*4 | F36: =Globales!$B$2+Globales!$B$3*5 | G36: =Globales!$B$2+Globales!$B$3*6 | H36: =Globales!$B$2+Globales!$B$3*7 | I36: =Globales!$B$2+Globales!$B$3*8 | J36: =Globales!$B$2+Globales!$B$3*9 | K36: =Globales!$B$2+Globales!$B$3*10 | L36: =Globales!$B$2+Globales!$B$3*11 | M36: =Globales!$B$2+Globales!$B$3*12 | N36: =IF(SUMPRODUCT(--(-B33:M33>B36:M36))=0,"cabe en el capital","NO cabe")
A37: Mes en que flujo neto ≥ 1 sueldo | B37: =IF(B32>=Globales!$B$9,1,"") | C37: =IF(C32>=Globales!$B$9,2,"") | D37: =IF(D32>=Globales!$B$9,3,"") | E37: =IF(E32>=Globales!$B$9,4,"") | F37: =IF(F32>=Globales!$B$9,5,"") | G37: =IF(G32>=Globales!$B$9,6,"") | H37: =IF(H32>=Globales!$B$9,7,"") | I37: =IF(I32>=Globales!$B$9,8,"") | J37: =IF(J32>=Globales!$B$9,9,"") | K37: =IF(K32>=Globales!$B$9,10,"") | L37: =IF(L32>=Globales!$B$9,11,"") | M37: =IF(M32>=Globales!$B$9,12,"") | N37: =IF(COUNT(B37:M37)=0,"no en 12 meses",MIN(B37:M37))
A39: Escenario optimista
A40: Precio escenario | B40: ='I1 Supuestos'!$B$4*'I1 Supuestos'!$D$36
A41: Ingreso neto unitario | B41: =IF('I1 Supuestos'!$B$5=1,B40/(1+'I1 Supuestos'!$B$6),B40)
A42: Costo variable total unitario | B42: ='I1 Supuestos'!$B$30+B40*'I1 Supuestos'!$B$7+'I1 Supuestos'!$B$8+B41*'I1 Supuestos'!$B$9
A43: Costos fijos mensuales | B43: ='I1 Supuestos'!$B$24
...

Sheet I1 Sensibilidad
A1: Sensibilidad — 1. Chatbot WhatsApp + panel (fichas 08+09+14) — escenario base, ±20 % una variable a la vez
A2: Resultado 12 m = Σ unidades × margen unitario − 12 × fijos − inversión; Σ unidades = u1·((1+g)^12−1)/g
A3: Variación | B3: 0.2
A4: Variable | B4: Valor base | C4: Resultado base | D4: Resultado −var | E4: Resultado +var | F4: Rango (abs)
A5: precio | B5: ='I1 Supuestos'!$B$4 | C5: =IF('I1 Supuestos'!$C$35=0,12*'I1 Supuestos'!$B$35,'I1 Supuestos'!$B$35*((1+'I1 Supuestos'!$C$35)^12-1)/'I1 Supuestos'!$C$35)*(IF('I1 Supuestos'!$B$5=1,('I1 Supuestos'!$B$4*'I1 Supuestos'!$D$35)/(1+'I1 Supuestos'!$B$6),('I1 Supuestos'!$B$4*'I1 Supuestos'!$D$35))-('I1 Supuestos'!$B$30+('I1 Supuestos'!$B$4*'I1 Supuestos'!$D$35)*'I1 Supuestos'!$B$7+'I1 Supuestos'!$B$8+IF('I1 Supuestos'!$B$5=1,('I1 Supuestos'!$B$4*'I1 Supuestos'!$D$35)/(1+'I1 Supuestos'!$B$6),('I1 Supuestos'!$B$4*'I1 Supuestos'!$D$35))*'I1 Supuestos'!$B$9))-12*'I1 Supuestos'!$B$24-'I1 Supuestos'!$B$18 | D5: =IF('I1 Supuestos'!$C$35=0,12*'I1 Supuestos'!$B$35,'I1 Supuestos'!$B$35*((1+'I1 Supuestos'!$C$35)^12-1)/'I1 Supuestos'!$C$35)*(IF('I1 Supuestos'!$B$5=1,(('I1 Supuestos'!$B$4*(1-$B$3))*'I1 Supuestos'!$D$35)/(1+'I1 Supuestos'!$B$6),(('I1 Supuestos'!$B$4*(1-$B$3))*'I1 Supuestos'!$D$35))-('I1 Supuestos'!$B$30+(('I1 Supuestos'!$B$4*(1-$B$3))*'I1 Supuestos'!$D$35)*'I1 Supuestos'!$B$7+'I1 Supuestos'!$B$8+IF('I1 Supuestos'!$B$5=1,(('I1 Supuestos'!$B$4*(1-$B$3))*'I1 Supuestos'!$D$35)/(1+'I1 Supuestos'!$B$6),(('I1 Supuestos'!$B$4*(1-$B$3))*'I1 Supuestos'!$D$35))*'I1 Supuestos'!$B$9))-12*'I1 Supuestos'!$B$24-'I1 Supuestos'!$B$18 | E5: =IF('I1 Supuestos'!$C$35=0,12*'I1 Supuestos'!$B$35,'I1 Supuestos'!$B$35*((1+'I1 Supuestos'!$C$35)^12-1)/'I1 Supuestos'!$C$35)*(IF('I1 Supuestos'!$B$5=1,(('I1 Supuestos'!$B$4*(1+$B$3))*'I1 Supuestos'!$D$35)/(1+'I1 Supuestos'!$B$6),(('I1 Supuestos'!$B$4*(1+$B$3))*'I1 Supuestos'!$D$35))-('I1 Supuestos'!$B$30+(('I1 Supuestos'!$B$4*(1+$B$3))*'I1 Supuestos'!$D$35)*'I1 Supuestos'!$B$7+'I1 Supuestos'!$B$8+IF('I1 Supuestos'!$B$5=1,(('I1 Supuestos'!$B$4*(1+$B$3))*'I1 Supuestos'!$D$35)/(1+'I1 Supuestos'!$B$6),(('I1 Supuestos'!$B$4*(1+$B$3))*'I1 Supuestos'!$D$35))*'I1 Supuestos'!$B$9))-12*'I1 Supuestos'!$B$24-'I1 Supuestos'!$B$18 | F5: =ABS(E5-D5)
A6: unidades_mes1 | B6: ='I1 Supuestos'!$B$35 | C6: =IF('I1 Supuestos'!$C$35=0,12*'I1 Supuestos'!$B$35,'I1 Supuestos'!$B$35*((1+'I1 Supuestos'!$C$35)^12-1)/'I1 Supuestos'!$C$35)*(IF('I1 Supuestos'!$B$5=1,('I1 Supuestos'!$B$4*'I1 Supuestos'!$D$35)/(1+'I1 Supuestos'!$B$6),('I1 Supuestos'!$B$4*'I1 Supuestos'!$D$35))-('I1 Supuestos'!$B$30+('I1 Supuestos'!$B$4*'I1 Supuestos'!$D$35)*'I1 Supuestos'!$B$7+'I1 Supuestos'!$B$8+IF('I1 Supuestos'!$B$5=1,('I1 Supuestos'!$B$4*'I1 Supuestos'!$D$35)/(1+'I1 Supuestos'!$B$6),('I1 Supuestos'!$B$4*'I1 Supuestos'!$D$35))*'I1 Supuestos'!$B$9))-12*'I1 Supuestos'!$B$24-'I1 Supuestos'!$B$18 | D6: =IF('I1 Supuestos'!$C$35=0,12*('I1 Supuestos'!$B$35*(1-$B$3)),('I1 Supuestos'!$B$35*(1-$B$3))*((1+'I1 Supuestos'!$C$35)^12-1)/'I1 Supuestos'!$C$35)*(IF('I1 Supuestos'!$B$5=1,('I1 Supuestos'!$B$4*'I1 Supuestos'!$D$35)/(1+'I1 Supuestos'!$B$6),('I1 Supuestos'!$B$4*'I1 Supuestos'!$D$35))-('I1 Supuestos'!$B$30+('I1 Supuestos'!$B$4*'I1 Supuestos'!$D$35)*'I1 Supuestos'!$B$7+'I1 Supuestos'!$B$8+IF('I1 Supuestos'!$B$5=1,('I1 Supuestos'!$B$4*'I1 Supuestos'!$D$35)/(1+'I1 Supuestos'!$B$6),('I1 Supuestos'!$B$4*'I1 Supuestos'!$D$35))*'I1 Supuestos'!$B$9))-12*'I1 Supuestos'!$B$24-'I1 Supuestos'!$B$18 | E6: =IF('I1 Supuestos'!$C$35=0,12*('I1 Supuestos'!$B$35*(1+$B$3)),('I1 Supuestos'!$B$35*(1+$B$3))*((1+'I1 Supuestos'!$C$35)^12-1)/'I1 Supuestos'!$C$35)*(IF('I1 Supuestos'!$B$5=1,('I1 Supuestos'!$B$4*'I1 Supuestos'!$D$35)/(1+'I1 Supuestos'!$B$6),('I1 Supuestos'!$B$4*'I1 Supuestos'!$D$35))-('I1 Supuestos'!$B$30+('I1 Supuestos'!$B$4*'I1 Supuestos'!$D$35)*'I1 Supuestos'!$B$7+'I1 Supuestos'!$B$8+IF('I1 Supuestos'!$B$5=1,('I1 Supuestos'!$B$4*'I1 Supuestos'!$D$35)/(1+'I1 Supuestos'!$B$6),('I1 Supuestos'!$B$4*'I1 Supuestos'!$D$35))*'I1 Supuestos'!$B$9))-12*'I1 Supuestos'!$B$24-'I1 Supuestos'!$B$18 | F6: =ABS(E6-D6)
A7: crecimiento | B7: ='I1 Supuestos'!$C$35 | C7: =IF('I1 Supuestos'!$C$35=0,12*'I1 Supuestos'!$B$35,'I1 Supuestos'!$B$35*((1+'I1 Supuestos'!$C$35)^12-1)/'I1 Supuestos'!$C$35)*(IF('I1 Supuestos'!$B$5=1,('I1 Supuestos'!$B$4*'I1 Supuestos'!$D$35)/(1+'I1 Supuestos'!$B$6),('I1 Supuestos'!$B$4*'I1 Supuestos'!$D$35))-('I1 Supuestos'!$B$30+('I1 Supuestos'!$B$4*'I1 Supuestos'!$D$35)*'I1 Supuestos'!$B$7+'I1 Supuestos'!$B$8+IF('I1 Supuestos'!$B$5=1,('I1 Supuestos'!$B$4*'I1 Supuestos'!$D$35)/(1+'I1 Supuestos'!$B$6),('I1 Supuestos'!$B$4*'I1 Supuestos'!$D$35))*'I1 Supuestos'!$B$9))-12*'I1 Supuestos'!$B$24-'I1 Supuestos'!$B$18 | D7: =IF(('I1 Supuestos'!$C$35*(1-$B$3))=0,12*'I1 Supuestos'!$B$35,'I1 Supuestos'!$B$35*((1+('I1 Supuestos'!$C$35*(1-$B$3)))^12-1)/('I1 Supuestos'!$C$35*(1-$B$3)))*(IF('I1 Supuestos'!$B$5=1,('I1 Supuestos'!$B$4*'I1 Supuestos'!$D$35)/(1+'I1 Supuestos'!$B$6),('I1 Supuestos'!$B$4*'I1 Supuestos'!$D$35))-('I1 Supuestos'!$B$30+('I1 Supuestos'!$B$4*'I1 Supuestos'!$D$35)*'I1 Supuestos'!$B$7+'I1 Supuestos'!$B$8+IF('I1 Supuestos'!$B$5=1,('I1 Supuestos'!$B$4*'I1 Supuestos'!$D$35)/(1+'I1 Supuestos'!$B$6),('I1 Supuestos'!$B$4*'I1 Supuestos'!$D$35))*'I1 Supuestos'!$B$9))-12*'I1 Supuestos'!$B$24-'I1 Supuestos'!$B$18 | E7: =IF(('I1 Supuestos'!$C$35*(1+$B$3))=0,12*'I1 Supuestos'!$B$35,'I1 Supuestos'!$B$35*((1+('I1 Supuestos'!$C$35*(1+$B$3)))^12-1)/('I1 Supuestos'!$C$35*(1+$B$3)))*(IF('I1 Supuestos'!$B$5=1,('I1 Supuestos'!$B$4*'I1 Supuestos'!$D$35)/(1+'I1 Supuestos'!$B$6),('I1 Supuestos'!$B$4*'I1 Supuestos'!$D$35))-('I1 Supuestos'!$B$30+('I1 Supuestos'!$B$4*'I1 Supuestos'!$D$35)*'I1 Supuestos'!$B$7+'I1 Supuestos'!$B$8+IF('I1 Supuestos'!$B$5=1,('I1 Supuestos'!$B$4*'I1 Supuestos'!$D$35)/(1+'I1 Supuestos'!$B$6),('I1 Supuestos'!$B$4*'I1 Supuestos'!$D$35))*'I1 Supuestos'!$B$9))-12*'I1 Supuestos'!$B$24-'I1 Supuestos'!$B$18 | F7: =ABS(E7-D7)
A8: cv_directo | B8: ='I1 Supuestos'!$B$30 | C8: =IF('I1 Supuestos'!$C$35=0,12*'I1 Supuestos'!$B$35,'I1 Supuestos'!$B$35*((1+'I1 Supuestos'!$C$35)^12-1)/'I1 Supuestos'!$C$35)*(IF('I1 Supuestos'!$B$5=1,('I1 Supuestos'!$B$4*'I1 Supuestos'!$D$35)/(1+'I1 Supuestos'!$B$6),('I1 Supuestos'!$B$4*'I1 Supuestos'!$D$35))-('I1 Supuestos'!$B$30+('I1 Supuestos'!$B$4*'I1 Supuestos'!$D$35)*'I1 Supuestos'!$B$7+'I1 Supuestos'!$B$8+IF('I1 Supuestos'!$B$5=1,('I1 Supuestos'!$B$4*'I1 Supuestos'!$D$35)/(1+'I1 Supuestos'!$B$6),('I1 Supuestos'!$B$4*'I1 Supuestos'!$D$35))*'I1 Supuestos'!$B$9))-12*'I1 Supuestos'!$B$24-'I1 Supuestos'!$B$18 | D8: =IF('I1 Supuestos'!$C$35=0,12*'I1 Supuestos'!$B$35,'I1 Supuestos'!$B$35*((1+'I1 Supuestos'!$C$35)^12-1)/'I1 Supuestos'!$C$35)*(IF('I1 Supuestos'!$B$5=1,('I1 Supuestos'!$B$4*'I1 Supuestos'!$D$35)/(1+'I1 Supuestos'!$B$6),('I1 Supuestos'!$B$4*'I1 Supuestos'!$D$35))-(('I1 Supuestos'!$B$30*(1-$B$3))+('I1 Supuestos'!$B$4*'I1 Supuestos'!$D$35)*'I1 Supuestos'!$B$7+'I1 Supuestos'!$B$8+IF('I1 Supuestos'!$B$5=1,('I1 Supuestos'!$B$4*'I1 Supuestos'!$D$35)/(1+'I1 Supuestos'!$B$6),('I1 Supuestos'!$B$4*'I1 Supuestos'!$D$35))*'I1 Supuestos'!$B$9))-12*'I1 Supuestos'!$B$24-'I1 Supuestos'!$B$18 | E8: =IF('I1 Supuestos'!$C$35=0,12*'I1 Supuestos'!$B$35,'I1 Supuestos'!$B$35*((1+'I1 Supuestos'!$C$35)^12-1)/'I1 Supuestos'!$C$35)*(IF('I1 Supuestos'!$B$5=1,('I1 Supuestos'!$B$4*'I1 Supuestos'!$D$35)/(1+'I1 Supuestos'!$B$6),('I1 Supuestos'!$B$4*'I1 Supuestos'!$D$35))-(('I1 Supuestos'!$B$30*(1+$B$3))+('I1 Supuestos'!$B$4*'I1 Supuestos'!$D$35)*'I1 Supuestos'!$B$7+'I1 Supuestos'!$B$8+IF('I1 Supuestos'!$B$5=1,('I1 Supuestos'!$B$4*'I1 Supuestos'!$D$35)/(1+'I1 Supuestos'!$B$6),('I1 Supuestos'!$B$4*'I1 Supuestos'!$D$35))*'I1 Supuestos'!$B$9))-12*'I1 Supuestos'!$B$24-'I1 Supuestos'!$B$18 | F8: =ABS(E8-D8)
A9: fijos | B9: ='I1 Supuestos'!$B$24 | C9: =IF('I1 Supuestos'!$C$35=0,12*'I1 Supuestos'!$B$35,'I1 Supuestos'!$B$35*((1+'I1 Supuestos'!$C$35)^12-1)/'I1 Supuestos'!$C$35)*(IF('I1 Supuestos'!$B$5=1,('I1 Supuestos'!$B$4*'I1 Supuestos'!$D$35)/(1+'I1 Supuestos'!$B$6),('I1 Supuestos'!$B$4*'I1 Supuestos'!$D$35))-('I1 Supuestos'!$B$30+('I1 Supuestos'!$B$4*'I1 Supuestos'!$D$35)*'I1 Supuestos'!$B$7+'I1 Supuestos'!$B$8+IF('I1 Supuestos'!$B$5=1,('I1 Supuestos'!$B$4*'I1 Supuestos'!$D$35)/(1+'I1 Supuestos'!$B$6),('I1 Supuestos'!$B$4*'I1 Supuestos'!$D$35))*'I1 Supuestos'!$B$9))-12*'I1 Supuestos'!$B$24-'I1 Supuestos'!$B$18 | D9: =IF('I1 Supuestos'!$C$35=0,12*'I1 Supuestos'!$B$35,'I1 Supuestos'!$B$35*((1+'I1 Supuestos'!$C$35)^12-1)/'I1 Supuestos'!$C$35)*(IF('I1 Supuestos'!$B$5=1,('I1 Supuestos'!$B$4*'I1 Supuestos'!$D$35)/(1+'I1 Supuestos'!$B$6),('I1 Supuestos'!$B$4*'I1 Supuestos'!$D$35))-('I1 Supuestos'!$B$30+('I1 Supuestos'!$B$4*'I1 Supuestos'!$D$35)*'I1 Supuestos'!$B$7+'I1 Supuestos'!$B$8+IF('I1 Supuestos'!$B$5=1,('I1 Supuestos'!$B$4*'I1 Supuestos'!$D$35)/(1+'I1 Supuestos'!$B$6),('I1 Supuestos'!$B$4*'I1 Supuestos'!$D$35))*'I1 Supuestos'!$B$9))-12*('I1 Supuestos'!$B$24*(1-$B$3))-'I1 Supuestos'!$B$18 | E9: =IF('I1 Supuestos'!$C$35=0,12*'I1 Supuestos'!$B$35,'I1 Supuestos'!$B$35*((1+'I1 Supuestos'!$C$35)^12-1)/'I1 Supuestos'!$C$35)*(IF('I1 Supuestos'!$B$5=1,('I1 Supuestos'!$B$4*'I1 Supuestos'!$D$35)/(1+'I1 Supuestos'!$B$6),('I1 Supuestos'!$B$4*'I1 Supuestos'!$D$35))-('I1 Supuestos'!$B$30+('I1 Supuestos'!$B$4*'I1 Supuestos'!$D$35)*'I1 Supuestos'!$B$7+'I1 Supuestos'!$B$8+IF('I1 Supuestos'!$B$5=1,('I1 Supuestos'!$B$4*'I1 Supuestos'!$D$35)/(1+'I1 Supuestos'!$B$6),('I1 Supuestos'!$B$4*'I1 Supuestos'!$D$35))*'I1 Supuestos'!$B$9))-12*('I1 Supuestos'!$B$24*(1+$B$3))-'I1 Supuestos'!$B$18 | F9: =ABS(E9-D9)
A10: inversion | B10: ='I1 Supuestos'!$B$18 | C10: =IF('I1 Supuestos'!$C$35=0,12*'I1 Supuestos'!$B$35,'I1 Supuestos'!$B$35*((1+'I1 Supuestos'!$C$35)^12-1)/'I1 Supuestos'!$C$35)*(IF('I1 Supuestos'!$B$5=1,('I1 Supuestos'!$B$4*'I1 Supuestos'!$D$35)/(1+'I1 Supuestos'!$B$6),('I1 Supuestos'!$B$4*'I1 Supuestos'!$D$35))-('I1 Supuestos'!$B$30+('I1 Supuestos'!$B$4*'I1 Supuestos'!$D$35)*'I1 Supuestos'!$B$7+'I1 Supuestos'!$B$8+IF('I1 Supuestos'!$B$5=1,('I1 Supuestos'!$B$4*'I1 Supuestos'!$D$35)/(1+'I1 Supuestos'!$B$6),('I1 Supuestos'!$B$4*'I1 Supuestos'!$D$35))*'I1 Supuestos'!$B$9))-12*'I1 Supuestos'!$B$24-'I1 Supuestos'!$B$18 | D10: =IF('I1 Supuestos'!$C$35=0,12*'I1 Supuestos'!$B$35,'I1 Supuestos'!$B$35*((1+'I1 Supuestos'!$C$35)^12-1)/'I1 Supuestos'!$C$35)*(IF('I1 Supuestos'!$B$5=1,('I1 Supuestos'!$B$4*'I1 Supuestos'!$D$35)/(1+'I1 Supuestos'!$B$6),('I1 Supuestos'!$B$4*'I1 Supuestos'!$D$35))-('I1 Supuestos'!$B$30+('I1 Supuestos'!$B$4*'I1 Supuestos'!$D$35)*'I1 Supuestos'!$B$7+'I1 Supuestos'!$B$8+IF('I1 Supuestos'!$B$5=1,('I1 Supuestos'!$B$4*'I1 Supuestos'!$D$35)/(1+'I1 Supuestos'!$B$6),('I1 Supuestos'!$B$4*'I1 Supuestos'!$D$35))*'I1 Supuestos'!$B$9))-12*'I1 Supuestos'!$B$24-('I1 Supuestos'!$B$18*(1-$B$3)) | E10: =IF('I1 Supuestos'!$C$35=0,12*'I1 Supuestos'!$B$35,'I1 Supuestos'!$B$35*((1+'I1 Supuestos'!$C$35)^12-1)/'I1 Supuestos'!$C$35)*(IF('I1 Supuestos'!$B$5=1,('I1 Supuestos'!$B$4*'I1 Supuestos'!$D$35)/(1+'I1 Supuestos'!$B$6),('I1 Supuestos'!$B$4*'I1 Supuestos'!$D$35))-('I1 Supuestos'!$B$30+('I1 Supuestos'!$B$4*'I1 Supuestos'!$D$35)*'I1 Supuestos'!$B$7+'I1 Supuestos'!$B$8+IF('I1 Supuestos'!$B$5=1,('I1 Supuestos'!$B$4*'I1 Supuestos'!$D$35)/(1+'I1 Supuestos'!$B$6),('I1 Supuestos'!$B$4*'I1 Supuestos'!$D$35))*'I1 Supuestos'!$B$9))-12*'I1 Supuestos'!$B$24-('I1 Supuestos'!$B$18*(1+$B$3)) | F10: =ABS(E10-D10)
A11: tasa_pasarela | B11: ='I1 Supuestos'!$B$7 | C11: =IF('I1 Supuestos'!$C$35=0,12*'I1 Supuestos'!$B$35,'I1 Supuestos'!$B$35*((1+'I1 Supuestos'!$C$35)^12-1)/'I1 Supuestos'!$C$35)*(IF('I1 Supuestos'!$B$5=1,('I1 Supuestos'!$B$4*'I1 Supuestos'!$D$35)/(1+'I1 Supuestos'!$B$6),('I1 Supuestos'!$B$4*'I1 Supuestos'!$D$35))-('I1 Supuestos'!$B$30+('I1 Supuestos'!$B$4*'I1 Supuestos'!$D$35)*'I1 Supuestos'!$B$7+'I1 Supuestos'!$B$8+IF('I1 Supuestos'!$B$5=1,('I1 Supuestos'!$B$4*'I1 Supuestos'!$D$35)/(1+'I1 Supuestos'!$B$6),('I1 Supuestos'!$B$4*'I1 Supuestos'!$D$35))*'I1 Supuestos'!$B$9))-12*'I1 Supuestos'!$B$24-'I1 Supuestos'!$B$18 | D11: =IF('I1 Supuestos'!$C$35=0,12*'I1 Supuestos'!$B$35,'I1 Supuestos'!$B$35*((1+'I1 Supuestos'!$C$35)^12-1)/'I1 Supuestos'!$C$35)*(IF('I1 Supuestos'!$B$5=1,('I1 Supuestos'!$B$4*'I1 Supuestos'!$D$35)/(1+'I1 Supuestos'!$B$6),('I1 Supuestos'!$B$4*'I1 Supuestos'!$D$35))-('I1 Supuestos'!$B$30+('I1 Supuestos'!$B$4*'I1 Supuestos'!$D$35)*('I1 Supuestos'!$B$7*(1-$B$3))+'I1 Supuestos'!$B$8+IF('I1 Supuestos'!$B$5=1,('I1 Supuestos'!$B$4*'I1 Supuestos'!$D$35)/(1+'I1 Supuestos'!$B$6),('I1 Supuestos'!$B$4*'I1 Supuestos'!$D$35))*'I1 Supuestos'!$B$9))-12*'I1 Supuestos'!$B$24-'I1 Supuestos'!$B$18 | E11: =IF('I1 Supuestos'!$C$35=0,12*'I1 Supuestos'!$B$35,'I1 Supuestos'!$B$35*((1+'I1 Supuestos'!$C$35)^12-1)/'I1 Supuestos'!$C$35)*(IF('I1 Supuestos'!$B$5=1,('I1 Supuestos'!$B$4*'I1 Supuestos'!$D$35)/(1+'I1 Supuestos'!$B$6),('I1 Supuestos'!$B$4*'I1 Supuestos'!$D$35))-('I1 Supuestos'!$B$30+('I1 Supuestos'!$B$4*'I1 Supuestos'!$D$35)*('I1 Supuestos'!$B$7*(1+$B$3))+'I1 Supuestos'!$B$8+IF('I1 Supuestos'!$B$5=1,('I1 Supuestos'!$B$4*'I1 Supuestos'!$D$35)/(1+'I1 Supuestos'!$B$6),('I1 Supuestos'!$B$4*'I1 Supuestos'!$D$35))*'I1 Supuestos'!$B$9))-12*'I1 Supuestos'!$B$24-'I1 Supuestos'!$B$18 | F11: =ABS(E11-D11)
A12: tasa_impuesto_renta | B12: ='I1 Supuestos'!$B$9 | C12: =IF('I1 Supuestos'!$C$35=0,12*'I1 Supuestos'!$B$35,'I1 Supuestos'!$B$35*((1+'I1 Supuestos'!$C$35)^12-1)/'I1 Supuestos'!$C$35)*(IF('I1 Supuestos'!$B$5=1,('I1 Supuestos'!$B$4*'I1 Supuestos'!$D$35)/(1+'I1 Supuestos'!$B$6),('I1 Supuestos'!$B$4*'I1 Supuestos'!$D$35))-('I1 Supuestos'!$B$30+('I1 Supuestos'!$B$4*'I1 Supuestos'!$D$35)*'I1 Supuestos'!$B$7+'I1 Supuestos'!$B$8+IF('I1 Supuestos'!$B$5=1,('I1 Supuestos'!$B$4*'I1 Supuestos'!$D$35)/(1+'I1 Supuestos'!$B$6),('I1 Supuestos'!$B$4*'I1 Supuestos'!$D$35))*'I1 Supuestos'!$B$9))-12*'I1 Supuestos'!$B$24-'I1 Supuestos'!$B$18 | D12: =IF('I1 Supuestos'!$C$35=0,12*'I1 Supuestos'!$B$35,'I1 Supuestos'!$B$35*((1+'I1 Supuestos'!$C$35)^12-1)/'I1 Supuestos'!$C$35)*(IF('I1 Supuestos'!$B$5=1,('I1 Supuestos'!$B$4*'I1 Supuestos'!$D$35)/(1+'I1 Supuestos'!$B$6),('I1 Supuestos'!$B$4*'I1 Supuestos'!$D$35))-('I1 Supuestos'!$B$30+('I1 Supuestos'!$B$4*'I1 Supuestos'!$D$35)*'I1 Supuestos'!$B$7+'I1 Supuestos'!$B$8+IF('I1 Supuestos'!$B$5=1,('I1 Supuestos'!$B$4*'I1 Supuestos'!$D$35)/(1+'I1 Supuestos'!$B$6),('I1 Supuestos'!$B$4*'I1 Supuestos'!$D$35))*('I1 Supuestos'!$B$9*(1-$B$3))))-12*'I1 Supuestos'!$B$24-'I1 Supuestos'!$B$18 | E12: =IF('I1 Supuestos'!$C$35=0,12*'I1 Supuestos'!$B$35,'I1 Supuestos'!$B$35*((1+'I1 Supuestos'!$C$35)^12-1)/'I1 Supuestos'!$C$35)*(IF('I1 Supuestos'!$B$5=1,('I1 Supuestos'!$B$4*'I1 Supuestos'!$D$35)/(1+'I1 Supuestos'!$B$6),('I1 Supuestos'!$B$4*'I1 Supuestos'!$D$35))-('I1 Supuestos'!$B$30+('I1 Supuestos'!$B$4*'I1 Supuestos'!$D$35)*'I1 Supuestos'!$B$7+'I1 Supuestos'!$B$8+IF('I1 Supuestos'!$B$5=1,('I1 Supuestos'!$B$4*'I1 Supuestos'!$D$35)/(1+'I1 Supuestos'!$B$6),('I1 Supuestos'!$B$4*'I1 Supuestos'!$D$35))*('I1 Supuestos'!$B$9*(1+$B$3))))-12*'I1 Supuestos'!$B$24-'I1 Supuestos'!$B$18 | F12: =ABS(E12-D12)
A14: La variable con mayor 'Rango' es la que más mueve el resultado.

Sheet I2 Supuestos
A1: Idea: 2. Cliente incógnito + micro-capacitación (ficha 10)
A2: Unidad: un servicio: visita incógnita + informe + sesión de capacitación
A3: Concepto | B3: Valor | C3: Origen | D3: Nota
A4: Precio de venta al cliente (S/) | B4: 180 | C4: SUPUESTO: por validar — dentro del rango S/ 120–250 de la ficha 10; S-09 fija el piso en S/ 100; con IGV incluido
A5: ¿Precio incluye IGV? (1 = sí, 0 = no) | B5: 1 | C5: regla
A6: Tasa IGV | B6: 0.18 | C6: VERIFICADO: TUO Ley del IGV (16 %) + IPM (2 %) = 18 %, vigente; sin informe legal aún — confirmar con asesor-legal-tributario-peru | D6: precio al cliente con IGV incluido
A7: Comisión pasarela (%) | B7: 0 | C7: SUPUESTO: por validar — cobro por Yape/Plin o transferencia entre personas naturales, sin comisión; la variante con Culqi (3,44 % + US$ 0,20) se calcula aparte
A8: Comisión pasarela fija por transacción (S/) | B8: 0 | C8: SUPUESTO: por validar — igual que tasa_pasarela
A9: Impuesto a la renta (% sobre ingreso neto) | B9: 0.015 | C9: SUPUESTO: por validar — RER (1,5 % de ingresos netos mensuales) como régimen uniforme y conservador para las cinco ideas; permite emitir factura a negocios. Variantes Nuevo RUS y 4.ª categoría se calculan aparte. Lo define el asesor legal en la Etapa 2
A10: Horas fijas por semana | B10: 3 | C10: ESTIMADO: venta por mensaje directo, contenido en redes y coordinación
A11: Horas por unidad vendida | B11: 6 | C11: ESTIMADO: ficha 10: visita 1–1,5 h + informe 2 h + capacitación 1–1,5 h + coordinación 1 h
A13: Inversión inicial (S/)
A14: consumo en 3 visitas de muestra (portafolio de informes) | B14: 75 | C14: ESTIMADO: ficha 10: S/ 15–30 por visita × 3 visitas a S/ 25
A15: transporte a las 3 visitas de muestra | B15: 30 | C15: ESTIMADO: S/ 10 ida y vuelta en transporte público por visita
A16: plantilla de pauta e informe (Canva/Docs gratuitos) | B16: 0 | C16: ESTIMADO: herramientas gratuitas; se redacta desde cero (S-06)
A17: TOTAL inversión inicial (s/) | B17: =SUM(B14:B16) | C17: fórmula
A19: Costos fijos mensuales (S/)
A20: promoción mínima en Instagram (publicaciones impulsadas) | B20: 40 | C20: SUPUESTO: por validar — mínimo para llegar a dueños sin prospección en frío (F4)
A21: herramientas digitales (Canva, Google gratuitos) | B21: 0 | C21: ESTIMADO: planes gratuitos
A22: contabilidad / declaraciones | B22: 0 | C22: SUPUESTO: por validar — declaran ellos mismos en SUNAT Virtual; un contador costaría S/ 50–150/mes
A23: TOTAL costos fijos mensuales (s/) | B23: =SUM(B20:B22) | C23: fórmula
A25: Costo variable directo por unidad (S/)
A26: consumo durante la visita incógnita | B26: 25 | C26: ESTIMADO: ficha 10 (S/ 15–30)
A27: transporte: visita + sesión de capacitación | B27: 20 | C27: ESTIMADO: 2 desplazamientos ida y vuelta × S/ 10 en Lima Norte
A28: material de la sesión (impresiones) | B28: 5 | C28: ESTIMADO: ~10 hojas impresas
A29: TOTAL costo variable directo por unidad (s/) | B29: =SUM(B26:B28) | C29: fórmula
A31: Escenarios
A32: Escenario | B32: Unidades mes 1 | C32: Crecimiento mensual | D32: Factor precio | E32: Origen
A33: pesimista | B33: 1 | C33: 0 | D33: 0.75 | E33: SUPUESTO: por validar — 1 servicio al mes a conocidos con 25 % de descuento y sin referidos: los dueños esperan el informe gratis (ficha 10)
A34: base | B34: 2 | C34: 0.15 | D34: 1 | E34: SUPUESTO: por validar — 2 locales en el mes 1 (conocidos y locales que ya frecuentan) y +15 %/mes por referidos entre dueños
A35: optimista | B35: 3 | C35: 0.2 | D35: 1 | E35: SUPUESTO: por validar — 3 en el mes 1 y +20 %/mes; cada cliente refiere a otro dueño del barrio
A37: Horas/semana requeridas (pico: mes 12 del escenario base) | B37: ='I2 Supuestos'!$B$10+'I2 Supuestos'!$B$11*'I2 Supuestos'!$B$34*(1+'I2 Supuestos'!$C$34)^(12-1)/(4.333333333333333) | C37: ESTIMADO: horas fijas/semana + horas por unidad × unidades del mes 12 del escenario base ÷ 4,33 semanas/mes (pico del año 1)
A38: Rango del precio por validar (mín – máx) | B38: 120 | C38: 250 | D38: ver hoja Unitario

Sheet I2 Unitario
A1: Economía unitaria — 2. Cliente incógnito + micro-capacitación (ficha 10) (precio de lista)
A2: Concepto | B2: S/ | C2: Fórmula
A3: Precio al cliente | B3: ='I2 Supuestos'!$B$4 | C3: '='I2 Supuestos'!$B$4
A4: Ingreso neto (sin IGV) | B4: =IF('I2 Supuestos'!$B$5=1,'I2 Unitario'!$B$3/(1+'I2 Supuestos'!$B$6),'I2 Unitario'!$B$3) | C4: '=IF('I2 Supuestos'!$B$5=1,'I2 Unitario'!$B$3/(1+'I2 Supuestos'!$B$6),'I2 Unitario'!$B$3)
A5: Comisión pasarela | B5: ='I2 Unitario'!$B$3*'I2 Supuestos'!$B$7+'I2 Supuestos'!$B$8 | C5: '='I2 Unitario'!$B$3*'I2 Supuestos'!$B$7+'I2 Supuestos'!$B$8
A6: Impuesto a la renta | B6: ='I2 Unitario'!$B$4*'I2 Supuestos'!$B$9 | C6: '='I2 Unitario'!$B$4*'I2 Supuestos'!$B$9
A7: Costo variable directo | B7: ='I2 Supuestos'!$B$29 | C7: '='I2 Supuestos'!$B$29
A8: Costo variable total | B8: ='I2 Unitario'!$B$7+'I2 Unitario'!$B$5+'I2 Unitario'!$B$6 | C8: '='I2 Unitario'!$B$7+'I2 Unitario'!$B$5+'I2 Unitario'!$B$6
A9: Margen por unidad | B9: ='I2 Unitario'!$B$4-'I2 Unitario'!$B$8 | C9: '='I2 Unitario'!$B$4-'I2 Unitario'!$B$8
A10: Margen % sobre ingreso neto | B10: =IF('I2 Unitario'!$B$4=0,0,'I2 Unitario'!$B$9/'I2 Unitario'!$B$4) | C10: '=IF('I2 Unitario'!$B$4=0,0,'I2 Unitario'!$B$9/'I2 Unitario'!$B$4)
A11: Costos fijos mensuales | B11: ='I2 Supuestos'!$B$23 | C11: '='I2 Supuestos'!$B$23
A12: Punto de equilibrio (unidades/mes) | B12: =IF('I2 Unitario'!$B$9>0,'I2 Unitario'!$B$11/'I2 Unitario'!$B$9,"no alcanzable") | C12: '=IF('I2 Unitario'!$B$9>0,'I2 Unitario'!$B$11/'I2 Unitario'!$B$9,"no alcanzable")
A13: Punto de equilibrio (S/ ventas/mes) | B13: =IF(ISNUMBER('I2 Unitario'!$B$12),'I2 Unitario'!$B$12*'I2 Unitario'!$B$3,"no alcanzable") | C13: '=IF(ISNUMBER('I2 Unitario'!$B$12),'I2 Unitario'!$B$12*'I2 Unitario'!$B$3,"no alcanzable")
A14: Inversión inicial | B14: ='I2 Supuestos'!$B$17 | C14: '='I2 Supuestos'!$B$17
A15: F1: inversión ≤ tope | B15: =IF('I2 Unitario'!$B$14<=Globales!$B$4,"sí","NO") | C15: '=IF('I2 Unitario'!$B$14<=Globales!$B$4,"sí","NO")
A16: F1: fijos ≤ tope mensual | B16: =IF('I2 Unitario'!$B$11<=Globales!$B$5,"sí","NO") | C16: '=IF('I2 Unitario'!$B$11<=Globales!$B$5,"sí","NO")
A17: Unidades/mes para cubrir 1 sueldo | B17: =IF('I2 Unitario'!$B$9>0,('I2 Unitario'!$B$11+Globales!$B$9)/'I2 Unitario'!$B$9,"no alcanzable") | C17: '=IF('I2 Unitario'!$B$9>0,('I2 Unitario'!$B$11+Globales!$B$9)/'I2 Unitario'!$B$9,"no alcanzable")
A18: Horas/semana para cubrir 1 sueldo | B18: =IF(ISNUMBER('I2 Unitario'!$B$17),'I2 Supuestos'!$B$10+'I2 Supuestos'!$B$11*'I2 Unitario'!$B$17/(4.333333333333333),"n/a") | C18: '=IF(ISNUMBER('I2 Unitario'!$B$17),'I2 Supuestos'!$B$10+'I2 Supuestos'!$B$11*'I2 Unitario'!$B$17/(4.333333333333333),"n/a")
A19: Unidades/mes para cubrir 2 sueldos | B19: =IF('I2 Unitario'!$B$9>0,('I2 Unitario'!$B$11+2*Globales!$B$9)/'I2 Unitario'!$B$9,"no alcanzable") | C19: '=IF('I2 Unitario'!$B$9>0,('I2 Unitario'!$B$11+2*Globales!$B$9)/'I2 Unitario'!$B$9,"no alcanzable")
A20: Horas/semana para cubrir 2 sueldos | B20: =IF(ISNUMBER('I2 Unitario'!$B$19),'I2 Supuestos'!$B$10+'I2 Supuestos'!$B$11*'I2 Unitario'!$B$19/(4.333333333333333),"n/a") | C20: '=IF(ISNUMBER('I2 Unitario'!$B$19),'I2 Supuestos'!$B$10+'I2 Supuestos'!$B$11*'I2 Unitario'!$B$19/(4.333333333333333),"n/a")
A22: Variantes (mismo precio de lista) | B22: Margen/u
A23: Nuevo RUS cat. 1: sin IGV, sin renta %, +cuota como fijo → margen | B23: ='I2 Unitario'!$B$3-('I2 Unitario'!$B$7+'I2 Unitario'!$B$5) | C23: '='I2 Unitario'!$B$3-('I2 Unitario'!$B$7+'I2 Unitario'!$B$5)
A24: Nuevo RUS: punto de equilibrio (u/mes) | B24: =IF('I2 Unitario'!$B$23>0,('I2 Unitario'!$B$11+Globales!$B$10)/'I2 Unitario'!$B$23,"no alcanzable") | C24: '=IF('I2 Unitario'!$B$23>0,('I2 Unitario'!$B$11+Globales!$B$10)/'I2 Unitario'!$B$23,"no alcanzable")
A25: 4.ª categoría: sin IGV, retención 8 % → margen | B25: ='I2 Unitario'!$B$3-('I2 Unitario'!$B$7+'I2 Unitario'!$B$5+'I2 Unitario'!$B$3*Globales!$B$11) | C25: '='I2 Unitario'!$B$3-('I2 Unitario'!$B$7+'I2 Unitario'!$B$5+'I2 Unitario'!$B$3*Globales!$B$11)
A26: RER + pasarela Culqi → margen | B26: ='I2 Unitario'!$B$4-('I2 Unitario'!$B$7+'I2 Unitario'!$B$3*Globales!$B$12+Globales!$B$13+'I2 Unitario'!$B$6) | C26: '='I2 Unitario'!$B$4-('I2 Unitario'!$B$7+'I2 Unitario'!$B$3*Globales!$B$12+Globales!$B$13+'I2 Unitario'!$B$6)
A27: Margen/u con precio mínimo del rango | B27: =IF('I2 Supuestos'!$B$5=1,'I2 Supuestos'!$B$38/(1+'I2 Supuestos'!$B$6),'I2 Supuestos'!$B$38)-('I2 Unitario'!$B$7+'I2 Supuestos'!$B$38*'I2 Supuestos'!$B$7+'I2 Supuestos'!$B$8+IF('I2 Supuestos'!$B$5=1,'I2 Supuestos'!$B$38/(1+'I2 Supuestos'!$B$6),'I2 Supuestos'!$B$38)*'I2 Supuestos'!$B$9) | C27: '=IF('I2 Supuestos'!$B$5=1,'I2 Supuestos'!$B$38/(1+'I2 Supuestos'!$B$6),'I2 Supuestos'!$B$38)-('I2 Unitario'!$B$7+'I2 Supuestos'!$B$38*'I2 Supuestos'!$B$7+'I2 Supuestos'!$B$8+IF('I2 Supuestos'!$B$5=1,'I2 Supuestos'!$B$38/(1+'I2 Supuestos'!$B$6),'I2 Supuestos'!$B$38)*'I2 Supuestos'!$B$9)
A28: Margen/u con precio máximo del rango | B28: =IF('I2 Supuestos'!$B$5=1,'I2 Supuestos'!$C$38/(1+'I2 Supuestos'!$B$6),'I2 Supuestos'!$C$38)-('I2 Unitario'!$B$7+'I2 Supuestos'!$C$38*'I2 Supuestos'!$B$7+'I2 Supuestos'!$B$8+IF('I2 Supuestos'!$B$5=1,'I2 Supuestos'!$C$38/(1+'I2 Supuestos'!$B$6),'I2 Supuestos'!$C$38)*'I2 Supuestos'!$B$9) | C28: '=IF('I2 Supuestos'!$B$5=1,'I2 Supuestos'!$C$38/(1+'I2 Supuestos'!$B$6),'I2 Supuestos'!$C$38)-('I2 Unitario'!$B$7+'I2 Supuestos'!$C$38*'I2 Supuestos'!$B$7+'I2 Supuestos'!$B$8+IF('I2 Supuestos'!$B$5=1,'I2 Supuestos'!$C$38/(1+'I2 Supuestos'!$B$6),'I2 Supuestos'!$C$38)*'I2 Supuestos'!$B$9)

Sheet I2 Flujo
A1: Flujo de caja a 12 meses — 2. Cliente incógnito + micro-capacitación (ficha 10). Escenarios, no predicciones.
A3: Escenario pesimista
A4: Precio escenario | B4: ='I2 Supuestos'!$B$4*'I2 Supuestos'!$D$33
A5: Ingreso neto unitario | B5: =IF('I2 Supuestos'!$B$5=1,B4/(1+'I2 Supuestos'!$B$6),B4)
A6: Costo variable total unitario | B6: ='I2 Supuestos'!$B$29+B4*'I2 Supuestos'!$B$7+'I2 Supuestos'!$B$8+B5*'I2 Supuestos'!$B$9
A7: Costos fijos mensuales | B7: ='I2 Supuestos'!$B$23
A8: Inversión inicial | B8: ='I2 Supuestos'!$B$17
A9: Mes | B9: 1 | C9: 2 | D9: 3 | E9: 4 | F9: 5 | G9: 6 | H9: 7 | I9: 8 | J9: 9 | K9: 10 | L9: 11 | M9: 12 | N9: Total 12 m
A10: Unidades | B10: ='I2 Supuestos'!$B$33*(1+'I2 Supuestos'!$C$33)^(1-1) | C10: ='I2 Supuestos'!$B$33*(1+'I2 Supuestos'!$C$33)^(2-1) | D10: ='I2 Supuestos'!$B$33*(1+'I2 Supuestos'!$C$33)^(3-1) | E10: ='I2 Supuestos'!$B$33*(1+'I2 Supuestos'!$C$33)^(4-1) | F10: ='I2 Supuestos'!$B$33*(1+'I2 Supuestos'!$C$33)^(5-1) | G10: ='I2 Supuestos'!$B$33*(1+'I2 Supuestos'!$C$33)^(6-1) | H10: ='I2 Supuestos'!$B$33*(1+'I2 Supuestos'!$C$33)^(7-1) | I10: ='I2 Supuestos'!$B$33*(1+'I2 Supuestos'!$C$33)^(8-1) | J10: ='I2 Supuestos'!$B$33*(1+'I2 Supuestos'!$C$33)^(9-1) | K10: ='I2 Supuestos'!$B$33*(1+'I2 Supuestos'!$C$33)^(10-1) | L10: ='I2 Supuestos'!$B$33*(1+'I2 Supuestos'!$C$33)^(11-1) | M10: ='I2 Supuestos'!$B$33*(1+'I2 Supuestos'!$C$33)^(12-1) | N10: =SUM(B10:M10)
A11: Ingresos netos | B11: =B10*$B$5 | C11: =C10*$B$5 | D11: =D10*$B$5 | E11: =E10*$B$5 | F11: =F10*$B$5 | G11: =G10*$B$5 | H11: =H10*$B$5 | I11: =I10*$B$5 | ... M11: =M10*$B$5 | N11: =SUM(B11:M11)
A12: Costos variables | B12: =B10*$B$6 | C12: =C10*$B$6 | D12: =D10*$B$6 | E12: =E10*$B$6 | F12: =F10*$B$6 | G12: =G10*$B$6 | H12: =H10*$B$6 | I12: =I10*$B$6 | ... M12: =M10*$B$6 | N12: =SUM(B12:M12)
A13: Costos fijos | B13: =$B$7 | C13: =$B$7 | D13: =$B$7 | E13: =$B$7 | F13: =$B$7 | G13: =$B$7 | H13: =$B$7 | I13: =$B$7 | ... M13: =$B$7 | N13: =SUM(B13:M13)
A14: Flujo neto | B14: =B11-B12-B13 | C14: =C11-C12-C13 | D14: =D11-D12-D13 | E14: =E11-E12-E13 | F14: =F11-F12-F13 | G14: =G11-G12-G13 | H14: =H11-H12-H13 | I14: =I11-I12-I13 | ... M14: =M11-M12-M13 | N14: =SUM(B14:M14)
A15: Acumulado (tras inversión) | B15: =-$B$8+B14 | C15: =B15+C14 | D15: =C15+D14 | E15: =D15+E14 | F15: =E15+F14 | G15: =F15+G14 | H15: =G15+H14 | I15: =H15+I14 | J15: =I15+J14 | ... M15: =L15+M14 | N15: =M15
A16: Mes en que acumulado ≥ 0 | B16: =IF(B15>=0,1,"") | C16: =IF(C15>=0,2,"") | D16: =IF(D15>=0,3,"") | E16: =IF(E15>=0,4,"") | F16: =IF(F15>=0,5,"") | G16: =IF(G15>=0,6,"") | H16: =IF(H15>=0,7,"") | I16: =IF(I15>=0,8,"") | J16: =IF(J15>=0,9,"") | K16: =IF(K15>=0,10,"") | L16: =IF(L15>=0,11,"") | M16: =IF(M15>=0,12,"") | N16: =IF(COUNT(B16:M16)=0,"no en 12 meses",MIN(B16:M16))
A17: Horas/semana | B17: ='I2 Supuestos'!$B$10+'I2 Supuestos'!$B$11*B10/(4.333333333333333) | C17: ='I2 Supuestos'!$B$10+'I2 Supuestos'!$B$11*C10/(4.333333333333333) | D17: ='I2 Supuestos'!$B$10+'I2 Supuestos'!$B$11*D10/(4.333333333333333) | E17: ='I2 Supuestos'!$B$10+'I2 Supuestos'!$B$11*E10/(4.333333333333333) | F17: ='I2 Supuestos'!$B$10+'I2 Supuestos'!$B$11*F10/(4.333333333333333) | G17: ='I2 Supuestos'!$B$10+'I2 Supuestos'!$B$11*G10/(4.333333333333333) | H17: ='I2 Supuestos'!$B$10+'I2 Supuestos'!$B$11*H10/(4.333333333333333) | I17: ='I2 Supuestos'!$B$10+'I2 Supuestos'!$B$11*I10/(4.333333333333333) | ... M17: ='I2 Supuestos'!$B$10+'I2 Supuestos'!$B$11*M10/(4.333333333333333) | N17: =MAX(B17:M17)
A18: Capital disponible (inicial + aportes) | B18: =Globales!$B$2+Globales!$B$3*1 | C18: =Globales!$B$2+Globales!$B$3*2 | D18: =Globales!$B$2+Globales!$B$3*3 | E18: =Globales!$B$2+Globales!$B$3*4 | F18: =Globales!$B$2+Globales!$B$3*5 | G18: =Globales!$B$2+Globales!$B$3*6 | H18: =Globales!$B$2+Globales!$B$3*7 | I18: =Globales!$B$2+Globales!$B$3*8 | J18: =Globales!$B$2+Globales!$B$3*9 | K18: =Globales!$B$2+Globales!$B$3*10 | L18: =Globales!$B$2+Globales!$B$3*11 | M18: =Globales!$B$2+Globales!$B$3*12 | N18: =IF(SUMPRODUCT(--(-B15:M15>B18:M18))=0,"cabe en el capital","NO cabe")
A19: Mes en que flujo neto ≥ 1 sueldo | B19: =IF(B14>=Globales!$B$9,1,"") | C19: =IF(C14>=Globales!$B$9,2,"") | D19: =IF(D14>=Globales!$B$9,3,"") | E19: =IF(E14>=Globales!$B$9,4,"") | F19: =IF(F14>=Globales!$B$9,5,"") | G19: =IF(G14>=Globales!$B$9,6,"") | H19: =IF(H14>=Globales!$B$9,7,"") | I19: =IF(I14>=Globales!$B$9,8,"") | J19: =IF(J14>=Globales!$B$9,9,"") | K19: =IF(K14>=Globales!$B$9,10,"") | L19: =IF(L14>=Globales!$B$9,11,"") | M19: =IF(M14>=Globales!$B$9,12,"") | N19: =IF(COUNT(B19:M19)=0,"no en 12 meses",MIN(B19:M19))
A21: Escenario base
A22: Precio escenario | B22: ='I2 Supuestos'!$B$4*'I2 Supuestos'!$D$34
A23: Ingreso neto unitario | B23: =IF('I2 Supuestos'!$B$5=1,B22/(1+'I2 Supuestos'!$B$6),B22)
A24: Costo variable total unitario | B24: ='I2 Supuestos'!$B$29+B22*'I2 Supuestos'!$B$7+'I2 Supuestos'!$B$8+B23*'I2 Supuestos'!$B$9
A25: Costos fijos mensuales | B25: ='I2 Supuestos'!$B$23
A26: Inversión inicial | B26: ='I2 Supuestos'!$B$17
A27: Mes | B27: 1 | C27: 2 | D27: 3 | E27: 4 | F27: 5 | G27: 6 | H27: 7 | I27: 8 | J27: 9 | K27: 10 | L27: 11 | M27: 12 | N27: Total 12 m
A28: Unidades | B28: ='I2 Supuestos'!$B$34*(1+'I2 Supuestos'!$C$34)^(1-1) | C28: ='I2 Supuestos'!$B$34*(1+'I2 Supuestos'!$C$34)^(2-1) | D28: ='I2 Supuestos'!$B$34*(1+'I2 Supuestos'!$C$34)^(3-1) | E28: ='I2 Supuestos'!$B$34*(1+'I2 Supuestos'!$C$34)^(4-1) | F28: ='I2 Supuestos'!$B$34*(1+'I2 Supuestos'!$C$34)^(5-1) | G28: ='I2 Supuestos'!$B$34*(1+'I2 Supuestos'!$C$34)^(6-1) | H28: ='I2 Supuestos'!$B$34*(1+'I2 Supuestos'!$C$34)^(7-1) | I28: ='I2 Supuestos'!$B$34*(1+'I2 Supuestos'!$C$34)^(8-1) | J28: ='I2 Supuestos'!$B$34*(1+'I2 Supuestos'!$C$34)^(9-1) | K28: ='I2 Supuestos'!$B$34*(1+'I2 Supuestos'!$C$34)^(10-1) | L28: ='I2 Supuestos'!$B$34*(1+'I2 Supuestos'!$C$34)^(11-1) | M28: ='I2 Supuestos'!$B$34*(1+'I2 Supuestos'!$C$34)^(12-1) | N28: =SUM(B28:M28)
A29: Ingresos netos | B29: =B28*$B$23 | C29: =C28*$B$23 | D29: =D28*$B$23 | E29: =E28*$B$23 | F29: =F28*$B$23 | G29: =G28*$B$23 | H29: =H28*$B$23 | I29: =I28*$B$23 | ... M29: =M28*$B$23 | N29: =SUM(B29:M29)
A30: Costos variables | B30: =B28*$B$24 | C30: =C28*$B$24 | D30: =D28*$B$24 | E30: =E28*$B$24 | F30: =F28*$B$24 | G30: =G28*$B$24 | H30: =H28*$B$24 | I30: =I28*$B$24 | ... M30: =M28*$B$24 | N30: =SUM(B30:M30)
A31: Costos fijos | B31: =$B$25 | C31: =$B$25 | D31: =$B$25 | E31: =$B$25 | F31: =$B$25 | G31: =$B$25 | H31: =$B$25 | I31: =$B$25 | ... M31: =$B$25 | N31: =SUM(B31:M31)
A32: Flujo neto | B32: =B29-B30-B31 | C32: =C29-C30-C31 | D32: =D29-D30-D31 | E32: =E29-E30-E31 | F32: =F29-F30-F31 | G32: =G29-G30-G31 | H32: =H29-H30-H31 | I32: =I29-I30-I31 | ... M32: =M29-M30-M31 | N32: =SUM(B32:M32)
A33: Acumulado (tras inversión) | B33: =-$B$26+B32 | C33: =B33+C32 | D33: =C33+D32 | E33: =D33+E32 | F33: =E33+F32 | G33: =F33+G32 | H33: =G33+H32 | I33: =H33+I32 | J33: =I33+J32 | ... M33: =L33+M32 | N33: =M33
A34: Mes en que acumulado ≥ 0 | B34: =IF(B33>=0,1,"") | C34: =IF(C33>=0,2,"") | D34: =IF(D33>=0,3,"") | E34: =IF(E33>=0,4,"") | F34: =IF(F33>=0,5,"") | G34: =IF(G33>=0,6,"") | H34: =IF(H33>=0,7,"") | I34: =IF(I33>=0,8,"") | J34: =IF(J33>=0,9,"") | K34: =IF(K33>=0,10,"") | L34: =IF(L33>=0,11,"") | M34: =IF(M33>=0,12,"") | N34: =IF(COUNT(B34:M34)=0,"no en 12 meses",MIN(B34:M34))
A35: Horas/semana | B35: ='I2 Supuestos'!$B$10+'I2 Supuestos'!$B$11*B28/(4.333333333333333) | C35: ='I2 Supuestos'!$B$10+'I2 Supuestos'!$B$11*C28/(4.333333333333333) | D35: ='I2 Supuestos'!$B$10+'I2 Supuestos'!$B$11*D28/(4.333333333333333) | E35: ='I2 Supuestos'!$B$10+'I2 Supuestos'!$B$11*E28/(4.333333333333333) | F35: ='I2 Supuestos'!$B$10+'I2 Supuestos'!$B$11*F28/(4.333333333333333) | G35: ='I2 Supuestos'!$B$10+'I2 Supuestos'!$B$11*G28/(4.333333333333333) | H35: ='I2 Supuestos'!$B$10+'I2 Supuestos'!$B$11*H28/(4.333333333333333) | I35: ='I2 Supuestos'!$B$10+'I2 Supuestos'!$B$11*I28/(4.333333333333333) | ... M35: ='I2 Supuestos'!$B$10+'I2 Supuestos'!$B$11*M28/(4.333333333333333) | N35: =MAX(B35:M35)
A36: Capital disponible (inicial + aportes) | B36: =Globales!$B$2+Globales!$B$3*1 | C36: =Globales!$B$2+Globales!$B$3*2 | D36: =Globales!$B$2+Globales!$B$3*3 | E36: =Globales!$B$2+Globales!$B$3*4 | F36: =Globales!$B$2+Globales!$B$3*5 | G36: =Globales!$B$2+Globales!$B$3*6 | H36: =Globales!$B$2+Globales!$B$3*7 | I36: =Globales!$B$2+Globales!$B$3*8 | J36: =Globales!$B$2+Globales!$B$3*9 | K36: =Globales!$B$2+Globales!$B$3*10 | L36: =Globales!$B$2+Globales!$B$3*11 | M36: =Globales!$B$2+Globales!$B$3*12 | N36: =IF(SUMPRODUCT(--(-B33:M33>B36:M36))=0,"cabe en el capital","NO cabe")
A37: Mes en que flujo neto ≥ 1 sueldo | B37: =IF(B32>=Globales!$B$9,1,"") | C37: =IF(C32>=Globales!$B$9,2,"") | D37: =IF(D32>=Globales!$B$9,3,"") | E37: =IF(E32>=Globales!$B$9,4,"") | F37: =IF(F32>=Globales!$B$9,5,"") | G37: =IF(G32>=Globales!$B$9,6,"") | H37: =IF(H32>=Globales!$B$9,7,"") | I37: =IF(I32>=Globales!$B$9,8,"") | J37: =IF(J32>=Globales!$B$9,9,"") | K37: =IF(K32>=Globales!$B$9,10,"") | L37: =IF(L32>=Globales!$B$9,11,"") | M37: =IF(M32>=Globales!$B$9,12,"") | N37: =IF(COUNT(B37:M37)=0,"no en 12 meses",MIN(B37:M37))
A39: Escenario optimista
A40: Precio escenario | B40: ='I2 Supuestos'!$B$4*'I2 Supuestos'!$D$35
A41: Ingreso neto unitario | B41: =IF('I2 Supuestos'!$B$5=1,B40/(1+'I2 Supuestos'!$B$6),B40)
A42: Costo variable total unitario | B42: ='I2 Supuestos'!$B$29+B40*'I2 Supuestos'!$B$7+'I2 Supuestos'!$B$8+B41*'I2 Supuestos'!$B$9
A43: Costos fijos mensuales | B43: ='I2 Supuestos'!$B$23
...

Sheet I2 Sensibilidad
A1: Sensibilidad — 2. Cliente incógnito + micro-capacitación (ficha 10) — escenario base, ±20 % una variable a la vez
A2: Resultado 12 m = Σ unidades × margen unitario − 12 × fijos − inversión; Σ unidades = u1·((1+g)^12−1)/g
A3: Variación | B3: 0.2
A4: Variable | B4: Valor base | C4: Resultado base | D4: Resultado −var | E4: Resultado +var | F4: Rango (abs)
