Workbook

Sheet Inicio
A1: Plan de validación — Chatbot de WhatsApp (A) y Sorpresas y detalles (B)
A2: Ventana | B2: Martes 27 de octubre a domingo 22 de noviembre de 2026. Primera venta deseada: 1 de diciembre.
A3: Quién ejecuta | B3: Carlos e Indira. La agencia no ejecuta nada: diseñó el plan y calcula el desempate con los registros de ustedes.
A4: Qué paga cada uno | B4: Carlos: gastos del chatbot (S/ 30 de consumo en A1; chip S/ 15 solo si se vende el piloto, se paga con el cobro). Indira: gastos de las cajas (S/ 40–60 en B1; S/ 30–40 en B3 solo si B1 pasa). Total del plan: S/ 100–130.
A5: Tope de horas | B5: 10 horas por semana por persona. La hoja Calendario lo verifica automáticamente.
A6: Cómo usar este archivo | B6: 1) Lean 'A Chatbot' y 'B Detalles': cada fila es un paso con fecha, responsable, horas y qué hacer exactamente. 2) Cada día que trabajen, anoten horas reales y gasto real en las celdas amarillas y cambien el Estado. 3) Cuando tengan datos (entrevistas, pagos, costos), llénenlos en 'Registro de resultados': las celdas de criterio dicen solas PASA / REPETIR / NO PASA. 4) El 20 de noviembre, con todo lleno, la hoja 'Desempate' calcula el margen por hora de cada negocio. 5) Me traen los resultados con /actualizar.
A7: Leyenda | B7: Celdas AMARILLAS = las llenan ustedes. Celdas blancas = fijas (plan) o fórmulas: no las editen. Azul claro = chatbot. Naranja claro = cajas.
A8: Reglas que no se negocian | B8: No construir el chatbot completo antes de que alguien pague. No preparar alimentos en casa: solo dulces envasados de marca. No escribir a desconocidos en privado ni puerta a puerta. No gastar más de lo presupuestado por experimento aunque 'falte poco'.
A9: Los criterios de éxito | B9: Se fijaron antes de empezar y salen del modelo financiero. Si un experimento no pasa, no se fuerza: se sigue la regla escrita en su fila ('Qué se decide').
A10: Piloto técnico en la librería | B10: Decisión de Carlos del 2026-10-23: antes de prometer instalación a un cliente, se monta el bot completo en la librería de la mamá de Indira (filas A3t). Es trabajo EXTRA de Carlos (hasta 20 h) fuera del tope de validación; cuesta S/ 15 de chip. La librería NO cuenta como cliente pagado para el criterio A2: es familia y es el piloto técnico.
A11: Si ninguna pasa | B11: Se vuelve a la Fase 3: cliente incógnito si en las entrevistas 2 dueños dijeron que pagarían una evaluación; si no, el taller de apps con IA.
A13: Estados posibles | B13: Pendiente · En curso · Hecho · Pasó · Repetir con cambio · No pasó · No aplica
A15: Ejemplo de fila llena | B15: Paso A0-2, Estado 'Hecho', Horas reales 0,5, Resultado: 'Recibí el hello_world a las 21:10; captura guardada'. Así de corto basta.

Sheet Calendario
A1: Horas planificadas por semana y por persona (se calculan desde las hojas de pasos). Tope: 10 h/semana/persona.
A2: Semana | B2: Inicio | C2: Fin | D2: Carlos chatbot (validación) | E2: Carlos cajas | F2: Carlos validación | G2: ¿Carlos ≤ 10? | H2: Indira chatbot (validación) | I2: Indira cajas | J2: Indira validación | K2: ¿Indira ≤ 10? | L2: S/ chatbot | M2: S/ cajas | N2: S/ total | O2: Carlos piloto técnico (extra) | P2: Carlos TOTAL | Q2: ¿Carlos ≤ 20? | R2: Indira piloto técnico (extra) | S2: Indira TOTAL | T2: ¿Indira ≤ 20?
A3: W1 | B3: 46322 | C3: 46327 | D3: =SUMIFS('A Chatbot'!G$3:G$24,'A Chatbot'!$D$3:$D$24,">="&$B3,'A Chatbot'!$D$3:$D$24,"<="&$C3)-O3 -> 6 | E3: =SUMIFS('B Detalles'!G$3:G$15,'B Detalles'!$D$3:$D$15,">="&$B3,'B Detalles'!$D$3:$D$15,"<="&$C3) -> 1 | F3: =D3+E3 -> 7 | G3: =IF(F3<=10,"Sí","NO: recortar") -> Sí | H3: =SUMIFS('A Chatbot'!H$3:H$24,'A Chatbot'!$D$3:$D$24,">="&$B3,'A Chatbot'!$D$3:$D$24,"<="&$C3)-R3 -> 2 | I3: =SUMIFS('B Detalles'!H$3:H$15,'B Detalles'!$D$3:$D$15,">="&$B3,'B Detalles'!$D$3:$D$15,"<="&$C3) -> 4 | J3: =H3+I3 -> 6 | K3: =IF(J3<=10,"Sí","NO: recortar") -> Sí | L3: =SUMIFS('A Chatbot'!I$3:I$24,'A Chatbot'!$D$3:$D$24,">="&$B3,'A Chatbot'!$D$3:$D$24,"<="&$C3) -> 15 | M3: =SUMIFS('B Detalles'!I$3:I$15,'B Detalles'!$D$3:$D$15,">="&$B3,'B Detalles'!$D$3:$D$15,"<="&$C3) -> 50 | N3: =L3+M3 -> 65 | O3: ='A Chatbot'!G18 -> 4 | P3: =F3+O3 -> 11 | Q3: =IF(P3<=20,"Sí","NO: recortar") -> Sí | R3: ='A Chatbot'!H18 -> 1 | S3: =J3+R3 -> 7 | T3: =IF(S3<=20,"Sí","NO: recortar") -> Sí
A4: W2 | B4: 46328 | C4: 46334 | D4: =SUMIFS('A Chatbot'!G$3:G$24,'A Chatbot'!$D$3:$D$24,">="&$B4,'A Chatbot'!$D$3:$D$24,"<="&$C4)-O4 -> 8.5 | E4: =SUMIFS('B Detalles'!G$3:G$15,'B Detalles'!$D$3:$D$15,">="&$B4,'B Detalles'!$D$3:$D$15,"<="&$C4) -> 0.5 | F4: =D4+E4 -> 9 | G4: =IF(F4<=10,"Sí","NO: recortar") -> Sí | H4: =SUMIFS('A Chatbot'!H$3:H$24,'A Chatbot'!$D$3:$D$24,">="&$B4,'A Chatbot'!$D$3:$D$24,"<="&$C4)-R4 -> 4 | I4: =SUMIFS('B Detalles'!H$3:H$15,'B Detalles'!$D$3:$D$15,">="&$B4,'B Detalles'!$D$3:$D$15,"<="&$C4) -> 3.5 | J4: =H4+I4 -> 7.5 | K4: =IF(J4<=10,"Sí","NO: recortar") -> Sí | L4: =SUMIFS('A Chatbot'!I$3:I$24,'A Chatbot'!$D$3:$D$24,">="&$B4,'A Chatbot'!$D$3:$D$24,"<="&$C4) -> 30 | M4: =SUMIFS('B Detalles'!I$3:I$15,'B Detalles'!$D$3:$D$15,">="&$B4,'B Detalles'!$D$3:$D$15,"<="&$C4) -> 0 | N4: =L4+M4 -> 30 | O4: ='A Chatbot'!G19 -> 8 | P4: =F4+O4 -> 17 | Q4: =IF(P4<=20,"Sí","NO: recortar") -> Sí | R4: ='A Chatbot'!H19 -> 1.5 | S4: =J4+R4 -> 9 | T4: =IF(S4<=20,"Sí","NO: recortar") -> Sí
A5: W3 | B5: 46335 | C5: 46341 | D5: =SUMIFS('A Chatbot'!G$3:G$24,'A Chatbot'!$D$3:$D$24,">="&$B5,'A Chatbot'!$D$3:$D$24,"<="&$C5)-O5 -> 3 | E5: =SUMIFS('B Detalles'!G$3:G$15,'B Detalles'!$D$3:$D$15,">="&$B5,'B Detalles'!$D$3:$D$15,"<="&$C5) -> 1 | F5: =D5+E5 -> 4 | G5: =IF(F5<=10,"Sí","NO: recortar") -> Sí | H5: =SUMIFS('A Chatbot'!H$3:H$24,'A Chatbot'!$D$3:$D$24,">="&$B5,'A Chatbot'!$D$3:$D$24,"<="&$C5)-R5 -> 3 | I5: =SUMIFS('B Detalles'!H$3:H$15,'B Detalles'!$D$3:$D$15,">="&$B5,'B Detalles'!$D$3:$D$15,"<="&$C5) -> 5 | J5: =H5+I5 -> 8 | K5: =IF(J5<=10,"Sí","NO: recortar") -> Sí | L5: =SUMIFS('A Chatbot'!I$3:I$24,'A Chatbot'!$D$3:$D$24,">="&$B5,'A Chatbot'!$D$3:$D$24,"<="&$C5) -> 0 | M5: =SUMIFS('B Detalles'!I$3:I$15,'B Detalles'!$D$3:$D$15,">="&$B5,'B Detalles'!$D$3:$D$15,"<="&$C5) -> 35 | N5: =L5+M5 -> 35 | O5: ='A Chatbot'!G20 -> 6 | P5: =F5+O5 -> 10 | Q5: =IF(P5<=20,"Sí","NO: recortar") -> Sí | R5: ='A Chatbot'!H20 -> 1 | S5: =J5+R5 -> 9 | T5: =IF(S5<=20,"Sí","NO: recortar") -> Sí
A6: W4 | B6: 46342 | C6: 46348 | D6: =SUMIFS('A Chatbot'!G$3:G$24,'A Chatbot'!$D$3:$D$24,">="&$B6,'A Chatbot'!$D$3:$D$24,"<="&$C6)-O6 -> 5.5 | E6: =SUMIFS('B Detalles'!G$3:G$15,'B Detalles'!$D$3:$D$15,">="&$B6,'B Detalles'!$D$3:$D$15,"<="&$C6) -> 2 | F6: =D6+E6 -> 7.5 | G6: =IF(F6<=10,"Sí","NO: recortar") -> Sí | H6: =SUMIFS('A Chatbot'!H$3:H$24,'A Chatbot'!$D$3:$D$24,">="&$B6,'A Chatbot'!$D$3:$D$24,"<="&$C6)-R6 -> 1 | I6: =SUMIFS('B Detalles'!H$3:H$15,'B Detalles'!$D$3:$D$15,">="&$B6,'B Detalles'!$D$3:$D$15,"<="&$C6) -> 8 | J6: =H6+I6 -> 9 | K6: =IF(J6<=10,"Sí","NO: recortar") -> Sí | L6: =SUMIFS('A Chatbot'!I$3:I$24,'A Chatbot'!$D$3:$D$24,">="&$B6,'A Chatbot'!$D$3:$D$24,"<="&$C6) -> 15 | M6: =SUMIFS('B Detalles'!I$3:I$15,'B Detalles'!$D$3:$D$15,">="&$B6,'B Detalles'!$D$3:$D$15,"<="&$C6) -> 0 | N6: =L6+M6 -> 15 | O6: =0 -> 0 | P6: =F6+O6 -> 7.5 | Q6: =IF(P6<=20,"Sí","NO: recortar") -> Sí | R6: =0 -> 0 | S6: =J6+R6 -> 9 | T6: =IF(S6<=20,"Sí","NO: recortar") -> Sí
A7: TOTAL | D7: =SUM(D3:D6) -> 23 | E7: =SUM(E3:E6) -> 4.5 | F7: =SUM(F3:F6) -> 27.5 | H7: =SUM(H3:H6) -> 10 | I7: =SUM(I3:I6) -> 20.5 | J7: =SUM(J3:J6) -> 30.5 | L7: =SUM(L3:L6) -> 60 | M7: =SUM(M3:M6) -> 85 | N7: =SUM(N3:N6) -> 145 | O7: =SUM(O3:O6) -> 18 | P7: =SUM(P3:P6) -> 45.5 | R7: =SUM(R3:R6) -> 3.5 | S7: =SUM(S3:S6) -> 34
A9: Nota: la fila A3-3 (construcción del piloto) cuenta solo sus 7 h de la semana 4; del 23-nov al 6-dic son hasta 10 h/semana adicionales, fuera de esta ventana. La fila B4-2 cuenta en la semana 4 aunque las entregas sigan hasta el 29-nov.
A10: Ventanas libres en común: lunes, miércoles y viernes desde las 20:00; sábado; domingo tarde. Indira estudia martes y jueves 19:30–22:40 y domingos 10:00–14:00.
A11: Piloto técnico (A3t, decisión de Carlos del 2026-10-23): horas EXTRA fuera del tope de 10 h de validación; se controlan contra las 20 h semanales de cada socio. Si una semana marca NO, se recorta el piloto técnico, no la validación.

Sheet A Chatbot
A1: A Chatbot — pasos en orden. Amarillo = ustedes llenan. Fechas de 2026.
A2: Paso | B2: Experimento | C2: Qué hacer exactamente | D2: Inicio | E2: Fin | F2: Responsable | G2: Horas plan Carlos | H2: Horas plan Indira | I2: S/ plan | J2: Quién paga | K2: Criterio de éxito / qué se decide | L2: Estado | M2: Horas reales Carlos | N2: Horas reales Indira | O2: S/ real | P2: Resultado / notas
A3: A0-1 | B3: A0 Términos de Meta y número de prueba | C3: Crear cuenta de desarrollador en developers.facebook.com, crear una app y activar el producto WhatsApp. Anotar el número de prueba que Meta asigna. | D3: 46322 | E3: 46322 | F3: Carlos | G3: 1 | H3: 0 | I3: 0 | J3: — | K3: Hecho cuando la app existe y muestra el número de prueba. | L3: Pendiente
A4: A0-2 | B4: A0 | C4: Registrar los celulares de Carlos e Indira como destinatarios de prueba y enviar la plantilla hello_world. Guardar captura del mensaje recibido. | D4: 46323 | E4: 46323 | F4: Carlos | G4: 0.5 | H4: 0 | I4: 0 | J4: — | K4: PASA si Carlos recibe el mensaje real en su WhatsApp. Si Meta exige verificación previa y no se logra en 2 h: la demo de A2 se hace simulada en pantalla (S-40 descartado); A2 sigue igual. | L4: Pendiente
A5: A0-3 | B5: A0 | C5: Leer la página de precios de WhatsApp Business Platform para Perú y escribir una nota de 1 página con 4 datos: costo por mensaje (servicio/utilidad/marketing) desde el 1-oct-2026, cuota gratuita mensual, requisitos de verificación del negocio, y si un número puede estar a la vez en la app WhatsApp Business y en la API. Con enlace y fecha. | D5: 46324 | E5: 46324 | F5: Carlos | G5: 0.5 | H5: 0 | I5: 0 | J5: — | K5: Hecho cuando la nota tiene los 4 datos con enlace. Sirve para la oferta de A2 y para el costo variable del modelo (S-29). | L5: Pendiente
A6: A1-1 | B6: A1 Entrevistas a 5–6 dueños | C6: Reunión de los dos (miércoles 20:00): imprimir el guion de la hoja 'Guiones y ofertas', repartir contactos (Carlos: academia, galletas, cafetería; Indira: librería, agencia, su local), agendar cada entrevista por WhatsApp o en persona. | D6: 46323 | E6: 46323 | F6: Ambos | G6: 1 | H6: 1 | I6: 0 | J6: — | K6: Hecho cuando las 6 entrevistas tienen fecha. | L6: Pendiente
A7: A1-2 | B7: A1 | C7: Entrevista al dueño de la academia de marinera (amigo de Carlos). Guion de 5 preguntas, respuestas textuales en la hoja 'Registro de resultados'. | D7: 46324 | E7: 46327 | F7: Carlos | G7: 1.5 | H7: 0 | I7: 0 | J7: — | K7: Registrar las 5 respuestas. Si en la P4 dice sí, anotar la fecha. | L7: Pendiente
A8: A1-3 | B8: A1 | C8: Entrevista a la mamá de Indira (librería). Mismo guion. | D8: 46324 | E8: 46327 | F8: Indira | G8: 1.5 | H8: 0 | I8: 0 | J8: — | K8: Registrar las 5 respuestas. | L8: Pendiente
A9: A1-4 | B9: A1 | C9: Entrevista a las amigas de la agencia de contenido (como clientes potenciales y como fuente de referidos: sus clientes atienden WhatsApp). Mismo guion. | D9: 46325 | E9: 46330 | F9: Indira | G9: 0 | H9: 1 | I9: 0 | J9: — | K9: Registrar las 5 respuestas y cuántos clientes suyos atienden WhatsApp. | L9: Pendiente
A10: A1-5 | B10: A1 | C10: Videollamada con la amiga de las galletas. Mismo guion. Preguntar además si vende con registro sanitario o marca formal (dato para B, S-41). | D10: 46328 | E10: 46331 | F10: Carlos | G10: 1 | H10: 0 | I10: 0 | J10: — | K10: Registrar las 5 respuestas + registro sanitario sí/no. | L10: Pendiente
A11: A1-6 | B11: A1 | C11: Cafetería de Lima Norte que Carlos frecuenta: ir como cliente, consumir (S/ 15) y conversar con el dueño o encargado con el guion. No es venta: es conversación. | D11: 46329 | E11: 46333 | F11: Carlos | G11: 1.5 | H11: 0 | I11: 15 | J11: Carlos | K11: Registrar las 5 respuestas. | L11: Pendiente
A12: A1-7 | B12: A1 | C12: Tienda o cafetería que Indira frecuenta: igual que A1-6. | D12: 46329 | E12: 46333 | F12: Indira | G12: 0 | H12: 1.5 | I12: 15 | J12: Carlos | K12: Registrar las 5 respuestas. | L12: Pendiente
A13: A1-8 | B13: A1 | C13: Consolidar las respuestas en la tabla A1 de 'Registro de resultados'. La celda de criterio calcula sola si A1 pasó. | D13: 46334 | E13: 46334 | F13: Indira | G13: 0 | H13: 1 | I13: 0 | J13: — | K13: PASA si ≥ 3 de 5 eligen S/ 80 o más en la P3 y ≥ 1 da fecha en la P4. REPETIR si solo 2 nombran precio y es ≤ S/ 50 (en A2 se ofrece el módulo básico a S/ 50 → S/ 80). NO PASA si ≤ 1 nombra precio: A2 no se hace y el chatbot pasa a la banda 31-ene. Incógnito: ≥ 2 de 5 pagarían ≥ S/ 100 → sigue en reserva. | L13: Pendiente
A14: A2-1 | B14: A2 Demo y preventa del piloto | C14: Indira define los 5 indicadores del panel (consultas recibidas, respondidas por el bot, derivadas, tiempo de respuesta, consultas que terminaron en venta o matrícula) y revisa el texto de la oferta (hoja 'Guiones y ofertas'). | D14: 46330 | E14: 46330 | F14: Indira | G14: 0 | H14: 1.5 | I14: 0 | J14: — | K14: Hecho cuando los 5 indicadores están escritos y la oferta tiene precio y fechas. | L14: Pendiente
... A24: D-A | B24: D Desempate | C24: Consolidar los registros del chatbot (horas reales, S/ cobrados, costos) en la hoja 'Desempate'. Viernes 20-nov, 20:00, juntos. | D24: 46346 | E24: 46346 | F24: Ambos | G24: 1 | H24: 0 | I24: 0 | J24: — | K24: La hoja calcula el margen por hora. El Director lo registra en decisiones.md. | L24: Pendiente
C25: TOTAL | G25: =SUM(G3:G24) -> 41 | H25: =SUM(H3:H24) -> 13.5 | I25: =SUM(I3:I24) -> 60 | M25: =SUM(M3:M24) -> 0 | N25: =SUM(N3:N24) -> 0 | O25: =SUM(O3:O24) -> 0

Sheet B Detalles
A1: B Detalles — pasos en orden. Amarillo = ustedes llenan. Fechas de 2026.
A2: Paso | B2: Experimento | C2: Qué hacer exactamente | D2: Inicio | E2: Fin | F2: Responsable | G2: Horas plan Carlos | H2: Horas plan Indira | I2: S/ plan | J2: Quién paga | K2: Criterio de éxito / qué se decide | L2: Estado | M2: Horas reales Carlos | N2: Horas reales Indira | O2: S/ real | P2: Resultado / notas
A3: B1-1 | B3: B1 Costeo de una caja real | C3: Carlos pide por WhatsApp 2 cotizaciones a motorizados conocidos (o que atienden a la librería) y 1 en una app de envíos, para dos rutas: Independencia → Los Olivos e Independencia → Miraflores. Es compra de un servicio, no prospección. | D3: 46323 | E3: 46323 | F3: Carlos | G3: 1 | H3: 0 | I3: 0 | J3: — | K3: Anotar los 3 precios por ruta en la tabla B1. | L3: Pendiente
A4: B1-2 | B4: B1 | C4: Carlos lista 5 cuentas de Instagram de 'detalles Lima' con el precio de una caja comparable SIN alimentos preparados (anotar cuenta, producto, precio, fecha). Referencia ya verificada: SorprendeLima S/ 80–360, siempre con repostería o flores. | D4: 46325 | E4: 46325 | F4: Carlos | G4: 0 | H4: 0 | I4: 0 | J4: — | K4: Anotar las 5 en la tabla B1. (La hora de Carlos va en B1-1: 1 h total para B1-1 y B1-2 juntas, repartida 1 + 1 según el plan.) | L4: Pendiente
A5: B1-3 | B5: B1 | C5: Indira compra los insumos de UNA caja con la composición exacta que se venderá: caja rígida decorada, 3–4 dulces envasados de marca (con registro sanitario del fabricante), 1 peluche pequeño o 1 flor, tarjeta, globo sencillo, papel y cinta. Guardar boleta o foto de cada precio. | D5: 46326 | E5: 46326 | F5: Indira | G5: 0 | H5: 2 | I5: 50 | J5: Indira | K5: Gasto máximo S/ 60. Anotar cada precio en la tabla B1 (la suma se calcula sola). | L5: Pendiente
A6: B1-4 | B6: B1 | C6: Indira arma la caja cronometrada y toma 5 fotos con buena luz (serán las fotos de la oferta). | D6: 46326 | E6: 46326 | F6: Indira | G6: 0 | H6: 1.5 | I6: 0 | J6: — | K6: Anotar los minutos de armado en la tabla B1. | L6: Pendiente
A7: B1-5 | B7: B1 | C7: Indira completa la tabla de costeo en 'Registro de resultados'. La celda de criterio dice sola si B1 pasó. | D7: 46327 | E7: 46327 | F7: Indira | G7: 0 | H7: 0.5 | I7: 0 | J7: — | K7: PASA si insumos + empaque + motorizado Lima Norte ≤ S/ 40 (con precio S/ 80 con envío), ≥ 3 de 5 competidores entre S/ 60 y S/ 100, y armado ≤ 1 h. REPETIR si costo S/ 41–50: la preventa sale a S/ 95 / S/ 110 y se verifica que ≥ 3 competidores estén en ese rango. NO PASA si costo > S/ 50 o motorizado > S/ 20 en Lima Norte: B2 y B3 no se hacen; B se descarta por escrito. | L7: Pendiente
A8: B2-1 | B8: B2 Preventa pagada (2 semanas) | C8: Publicar la oferta exacta (hoja 'Guiones y ofertas') con las fotos de B1 en: estados de WhatsApp de ambos, Instagram de Indira (o cuenta nueva del negocio que ella crea), grupos de WhatsApp de la UPN de cada uno. Pedir a las amigas de la agencia que compartan (sin pago). NO escribir en privado a nadie que no haya preguntado. | D8: 46328 | E8: 46328 | F8: Ambos | G8: 0.5 | H8: 1 | I8: 0 | J8: — | K8: Hecho cuando está publicada en los 4 canales. | L8: Pendiente
A9: B2-2 | B9: B2 | C9: Indira responde consultas y registra cada pedido en la tabla B2: fecha, cliente, zona, precio, pagó adelantado sí/no, si es de fuera del círculo cercano, si pidió descuento, fecha de entrega elegida (16 a 29 nov). | D9: 46328 | E9: 46334 | F9: Indira | G9: 0 | H9: 2.5 | I9: 0 | J9: — | K9: Solo cuenta un pedido cuando el Yape o Plin está recibido. | L9: Pendiente
A10: B2-3 | B10: B2 | C10: Semana 2 de preventa: seguir respondiendo y registrando. Cierre: domingo 15 de noviembre, 23:59. Carlos cuadra los cobros recibidos contra la tabla. | D10: 46335 | E10: 46341 | F10: Ambos | G10: 0.5 | H10: 3 | I10: 0 | J10: — | K10: PASA si ≥ 6 pedidos pagados (≥ S/ 480), ≥ 2 de personas fuera del círculo cercano y ≥ 3 de cada 5 sin pedir descuento. REPETIR si 4–5 pedidos: se extiende hasta el 22-nov con segunda foto y una variante (p. ej., 'para él'); el umbral sigue en 6 acumulados. NO PASA si ≤ 3 pedidos o 0 de fuera del círculo: B se descarta por escrito; lo cobrado se entrega igual. | L10: Pendiente
A11: B3-1 | B11: B3 Anuncio mínimo (solo si B1 pasó) | C11: Indira impulsa la publicación de la oferta con botón a WhatsApp. Público: Lima Norte, 20–35 años, 5–6 días. Presupuesto total S/ 30–40. A cada consulta preguntar '¿cómo nos encontraste?' y anotarlo. | D11: 46337 | E11: 46337 | F11: Indira | G11: 0 | H11: 1 | I11: 35 | J11: Indira | K11: Registrar en la tabla B3: consultas atribuibles al anuncio, gasto real, pedidos pagados de desconocidos. | L11: Pendiente
A12: B3-2 | B12: B3 | C12: Responder las consultas del anuncio. Viernes 13-nov: Carlos e Indira revisan juntos las métricas del anuncio. | D12: 46338 | E12: 46341 | F12: Ambos | G12: 0.5 | H12: 1 | I12: 0 | J12: — | K12: PASA si ≥ 5 consultas por WhatsApp atribuibles, ≤ S/ 8 por consulta y ≥ 1 pedido pagado de un desconocido. NO PASA: aunque B2 pase, B queda como 'demanda solo de conocidos' y su crecimiento en el modelo baja a 0 %. No se repite con más dinero. | L12: Pendiente
A13: B4-1 | B13: B4 Entrega (solo si B2 pasó) | C13: Comprar los insumos de todos los pedidos con los adelantos recibidos (≈ S/ 40 por pedido). | D13: 46342 | E13: 46344 | F13: Indira | G13: 0 | H13: 2 | I13: 0 | J13: Adelantos | K13: Anotar el costo real por pedido en la tabla B2. | L13: Pendiente
A14: B4-2 | B14: B4 | C14: Sábado 21-nov: armar las cajas por lotes, cronometrando. Coordinar motorizados por fecha de entrega; enviar foto de la entrega a cada cliente. | D14: 46347 | E14: 46355 | F14: Ambos | G14: 2 | H14: 5 | I14: 0 | J14: Adelantos | K14: PASA si costo real promedio ≤ S/ 40 por pedido y ≤ 1,5 h por pedido entre armado y coordinación. Si se supera, la Etapa 2 recalcula con las cifras reales. | L14: Pendiente
A15: D-B | B15: D Desempate | C15: Consolidar los registros de las cajas (horas reales, S/ cobrados, costos) en la hoja 'Desempate'. Viernes 20-nov, 20:00, juntos. | D15: 46346 | E15: 46346 | F15: Ambos | G15: 0 | H15: 1 | I15: 0 | J15: — | K15: La hoja calcula el margen por hora. | L15: Pendiente
C16: TOTAL | G16: =SUM(G3:G15) -> 4.5 | H16: =SUM(H3:H15) -> 20.5 | I16: =SUM(I3:I15) -> 85 | M16: =SUM(M3:M15) -> 0 | N16: =SUM(N3:N15) -> 0 | O16: =SUM(O3:O15) -> 0

Sheet Guiones y ofertas
A1: GUION A1 — entrevista (5 preguntas, en este orden, sin sugerir respuestas; anotar textual)
A2: P1 (S-20) | B2: ¿Cuántos mensajes de clientes recibe por WhatsApp en una semana normal y quién los responde? → anotar número y quién.
A3: P2 (problema) | B3: ¿Cuáles son las 3 preguntas que más se repiten, y cuántas ventas o matrículas cree que pierde al mes por responder tarde o fuera de horario? → anotar cifra aunque sea aproximada.
A4: P3 (S-10, S-34) | B4: Si un asistente automático respondiera esas preguntas las 24 horas, derivara a usted lo que no sabe y le enviara cada semana cuántas consultas terminaron en venta, ¿cuánto pagaría al mes? Elija: nada / S/ 50 / S/ 100 / S/ 150 / S/ 200.
A5: P4 (S-08, S-14) | B5: ¿Aceptaría probarlo 30 días en un número nuevo del negocio pagando S/ 100 por adelantado, y qué fecha le vendría bien para empezar? → sí/no y fecha.
A6: P5 (incógnito, S-09) | B6: Aparte de eso: ¿pagaría S/ 100 a S/ 150 por una visita de cliente incógnito a su local, un informe de 2 páginas y 45 minutos de capacitación a su personal? ¿Cuánto? → monto y si hoy compra algo parecido.
A7: Cierre (S-28) | B7: Si respondió sí en la P4: ¿necesita factura o le basta boleta / Yape?
A9: OFERTA A2 — texto exacto del piloto | B9: "Piloto de 30 días: un asistente en un número nuevo de WhatsApp de su negocio que responde sus 10 preguntas más frecuentes a toda hora, le deriva lo que no sabe y le manda un reporte semanal con 5 indicadores. Precio del piloto: S/ 100, pagados por adelantado por Yape o Plin. Si sigue, S/ 150 al mes desde el segundo mes; si no, se apaga sin costo. Instalación en 14 días desde el pago; arranque a más tardar el lunes 30 de noviembre."
A10: Regla de cobro | B10: Se cobra SOLO si hay fecha de inicio ≤ 30-nov. Sin fecha no hay cobro. No se regala el primer mes.
A12: OFERTA B2 — texto exacto de la Caja Detalle | B12: "Caja Detalle — para cumpleaños, aniversario o 'me acordé de ti'. Caja decorada, 3 dulces de marca, peluche pequeño o flor, tarjeta con tu mensaje y globo. S/ 80 con envío incluido en Independencia, Los Olivos, San Martín de Porres y Comas; S/ 95 en el resto de Lima. Pago por Yape o Plin al hacer el pedido. Elige la fecha de entrega entre el lunes 16 y el domingo 29 de noviembre; te mandamos foto de la entrega. Pedidos hasta el domingo 15 de noviembre."
A13: Si B1 terminó en REPETIR | B13: Los precios pasan a S/ 95 (Lima Norte) / S/ 110 (resto de Lima). Todo lo demás igual.
A14: Canales permitidos | B14: Estados de WhatsApp de ambos · Instagram de Indira o cuenta nueva del negocio · grupos de WhatsApp de la UPN · amigas de la agencia compartiendo sin pago · anuncio B3 con métrica. Prohibido: mensajes en frío, puerta a puerta.
A16: CONTACTOS
A17: Academia de marinera | B17: Dueño, amigo cercano de Carlos → entrevista A1-2 (Carlos), demo A2-3 (Carlos). Candidato a piloto del chatbot.
A18: Librería | B18: Mamá de Indira → entrevista A1-3 (Indira), demo A2-3 (Indira). También: motorizado que atiende a la librería (B1-1).
A19: Agencia de contenido | B19: Amigas de la UPN, recién iniciada → entrevista A1-4 (Indira). Difusoras de la oferta B2 sin pago.
A20: Galletas | B20: Amiga que vende por redes → entrevista A1-5 (Carlos, videollamada). Preguntar registro sanitario (S-41).
A21: Cafetería / tienda de Lima Norte | B21: Una que frecuenta Carlos (A1-6) y una que frecuenta Indira (A1-7). Ir como clientes.
A23: AJUSTE 2026-10-22 — META (verificado en fuentes oficiales)
A24: A0: dónde entrar | B24: developers.facebook.com → App Dashboard → tu app → WhatsApp → API Setup. Ahí Meta asigna un número de prueba sin verificación ni tarjeta (Carlos lo confirmó el 22-oct: funciona, máximo 5 destinatarios). NO entrar por Business Suite / WhatsApp Manager: ahí aparece el flujo de verificación con documentos.
A25: A2: pregunta adicional (S-47) | B25: "La cuenta de WhatsApp Business y el número quedan a nombre de su negocio; usted registra su tarjeta en Meta solo para el excedente sobre los 1 000 mensajes gratuitos al mes. ¿Está de acuerdo?" → anotar sí/no.
A26: A3 / A3t: cómo se instala | B26: Cuenta y número a nombre del cliente (chip nuevo, nunca registrado en WhatsApp); Carlos con rol de administrador en su negocio y en la app. Sin verificar el negocio: un bot que solo responde dentro de la ventana de 24 h no toca el límite de 250. Aceptar los términos de la Cloud API antes de enviar. Verificación con RUC: Etapa 2.
A27: Webhook (paso 2 del panel) | B27: URL = dirección https del túnel terminada en /webhook; token = META_VERIFY_TOKEN del .env; luego suscribirse al campo 'messages'. No registrar el celular personal (Meta lo sacaría de WhatsApp). Si los mensajes reales no llegan con la app sin publicar, pasar la app a modo Live (política de privacidad).

Sheet Registro de resultados
A1: Registro de resultados — llenen las celdas amarillas. Las celdas 'Criterio' se calculan solas.
A3: A1 — Entrevistas (una fila por entrevista)
A4: Contacto | B4: Entrevistador | C4: Fecha | D4: P1 mensajes/semana | E4: P2 preguntas repetidas y ventas perdidas/mes | F4: P3 pagaría S/ al mes | G4: P4 acepta piloto | H4: P4 fecha inicio | I4: P5 incógnito S/ | J4: Cierre: factura | K4: Notas
A5: Academia de marinera
A6: Librería (mamá de Indira)
A7: Agencia de contenido
A8: Galletas
A9: Cafetería de Carlos
A10: Local de Indira
A11: Entrevistas completas | B11: =COUNTA(F5:F10) -> 0
A12: Eligen ≥ S/ 80 al mes (P3) | B12: =COUNTIF(F5:F10,">=80") -> 0
A13: Dan fecha de piloto (P4 = Sí) | B13: =COUNTIF(G5:G10,"Sí") -> 0
A14: Nombran algún precio > 0 (P3) | B14: =COUNTIF(F5:F10,">0") -> 0
A15: Reciben < 1 000 mensajes/mes (P1 < 231/semana) | B15: =COUNTIF(D5:D10,"<231") -> 0
A16: Incógnito: pagarían ≥ S/ 100 (P5) | B16: =COUNTIF(I5:I10,">=100") -> 0
A17: CRITERIO A1 | B17: =IF(B11<5,"Faltan entrevistas (mínimo 5)",IF(AND(B12>=3,B13>=1),"PASA → hacer A2",IF(B14=2,"REPETIR CON CAMBIO → A2 con módulo básico a S/ 50 → S/ 80","NO PASA → A2 no se hace; chatbot a banda 31-ene"))) -> Faltan entrevistas (mínimo 5)
A18: Incógnito (reserva) | B18: =IF(B11<5,"Pendiente",IF(B16>=2,"Sigue vivo en reserva","Se archiva")) -> Pendiente
A19: Costo variable del modelo (S-29) | B19: =IF(B11<5,"Pendiente",IF(B15>=4,"Se mantiene S/ 33,07","Recalcular S-29 con el volumen real")) -> Pendiente
A21: A2 — Pagos del piloto (una fila por cliente)
A22: Cliente | B22: Resultado de la demo | C22: Fecha de pago | D22: Monto pagado S/ | E22: Fecha de inicio acordada | F22: Confirma mes 2 (S/ 150) | G22: Mensualidad acordada S/ | H22: Notas | I22: Es familiar (no cuenta)
A29: Pagos recibidos de no familiares | B29: =COUNTIFS(D23:D28,">0",I23:I28,"<>Sí") -> 0
A30: S/ cobrados por adelantado | B30: =SUM(D23:D28) -> 0
A31: Compromisos 'sí cuando lo vea' | B31: =COUNTIF(B23:B28,"Sí cuando lo vea funcionando") -> 0
A32: Clientes que confirman mes 2 | B32: =COUNTIF(F23:F28,"Sí") -> 0
A33: CRITERIO A2 | B33: =IF(COUNTA(B23:B28)=0,"Pendiente",IF(B29>=2,"PASA (escenario base) → A3",IF(B29=1,"PASA (escenario pesimista) → A3",IF(B31>=2,"REPETIR CON CAMBIO → ofrecer 14 días gratis a UNO, plazo 22-nov","NO PASA → no se construye nada")))) -> Pendiente
A35: B1 — Costeo de la caja real
A36: Ítem | B36: S/ real | C36: Dónde se compró / nota
A37: Caja rígida decorada
A38: Dulce envasado 1
A39: Dulce envasado 2
A40: Dulce envasado 3
A41: Dulce envasado 4 (opcional)
A42: Peluche pequeño o flor
A43: Tarjeta
A44: Globo
A45: Papel y cinta
A46: Motorizado Lima Norte (menor de 3 cotizaciones)
A47: COSTO TOTAL POR PEDIDO | B47: =SUM(B37:B46) -> 0
A48: Motorizado Lima Norte (S/) | B48: =B46 -> 0
A49: Motorizado Lima centro-sur (S/)
...

Sheet Desempate
A1: Desempate — margen real por hora a 3 meses (MRH). Regla fijada el 2026-10-21, aceptada por los socios el 2026-10-22.
A2: Las celdas amarillas se llenan el viernes 20-nov con los registros reales. Lo demás se calcula. La versión oficial del cálculo vive en finanzas/modelo.py (--desempate); esta hoja debe dar lo mismo.
A4: A — CHATBOT
A5: S/ cobrados por adelantado (de Registro A2) | B5: ='Registro de resultados'!B30 -> 0 | C5: fórmula
A6: Costos directos reales del piloto: chip + Meta + IA + hosting (S/) | C6: llenar
A7: Clientes que confirman seguir el mes 2 (de Registro A2) | B7: ='Registro de resultados'!B32 -> 0 | C7: fórmula
A8: Mensualidad acordada por escrito (S/) | B8: 150 | C8: llenar si cambió; plan: 150
A9: Costo variable modelado por cliente al mes (S-29) | B9: 33.07 | C9: fijo del modelo
A10: Horas reales A0 + A1 + A2 (de 'A Chatbot', pasos A0-1 a A2-4, Carlos + Indira) | B10: =SUM('A Chatbot'!M3:N17) -> 0 | C10: fórmula
A11: Horas reales de construcción: piloto técnico A3t + réplica A3 (si no terminó: 30) | C11: llenar
A12: Horas de operación: 2 h × clientes × 2 meses | B12: =2*B7*2 -> 0 | C12: fórmula
A13: Margen A a 3 meses (S/) | B13: =B5-B6+2*(B8-B9)*B7 -> 0 | C13: fórmula
A14: Horas A | B14: =B10+IF(B11="",30,B11)+B12 -> 30 | C14: fórmula
A15: MRH A (S/ por hora) | B15: =IF(B14=0,0,B13/B14) -> 0 | C15: fórmula
A17: B — DETALLES
A18: S/ cobrados por adelantado (de Registro B2) | B18: ='Registro de resultados'!B75 -> 0 | C18: fórmula
A19: Costos reales de insumos, empaque y motorizado de esos pedidos (de Registro B2) | B19: ='Registro de resultados'!B78 -> 0 | C19: fórmula
A20: Horas reales B1 + B2 + B3 + B4 (de 'B Detalles', Carlos + Indira) | B20: =SUM('B Detalles'!M3:N14) -> 0 | C20: fórmula
A21: Margen B (S/) | B21: =B18-B19 -> 0 | C21: fórmula
A22: MRH B (S/ por hora) | B22: =IF(B20=0,0,B21/B20) -> 0 | C22: fórmula
A24: RESULTADO
A25: ¿A pasó A2? | B25: ='Registro de resultados'!B33 -> Pendiente | C25: fórmula
A26: ¿B pasó B2? | B26: ='Registro de resultados'!B81 -> Pendiente | C26: fórmula
A27: Recomendación de la agencia | B27: =IF(OR(B25="Pendiente",B26="Pendiente"),"Pendiente: faltan resultados",IF(AND(LEFT(B25,4)="PASA",LEFT(B26,4)="PASA"),IF(ABS(B15-B22)<0.2*MAX(B15,B22),"A (chatbot): diferencia < 20 %, gana la recurrencia",IF(B15>B22,"A (chatbot): mayor margen por hora","B (detalles): mayor margen por hora")),IF(LEFT(B25,4)="PASA","A (chatbot): la única que pasó",IF(LEFT(B26,4)="PASA","B (detalles): la única que pasó","Ninguna pasó → volver a Fase 3 (incógnito o taller)")))) -> Pendiente: faltan resultados | C27: fórmula
A28: Secundaria: % de soles de B cobrados fuera del círculo cercano | B28: =IF('Registro de resultados'!B75=0,0,SUMIFS('Registro de resultados'!D62:D73,'Registro de resultados'!E62:E73,"Sí",'Registro de resultados'!F62:F73,"Sí")/'Registro de resultados'!B75) -> 0 | C28: se reporta, no decide
A30: Ilustración del plan (solo escala, no es dato): A con 1 piloto y 30 h ≈ S/ 6/h; A con 2 pilotos ≈ S/ 10/h; B con 6 pedidos a costo S/ 40 ≈ S/ 10/h. El desempate está abierto.
